(0.003) 
            SELECT c.relname, c.relkind
            FROM pg_catalog.pg_class c
            LEFT JOIN pg_catalog.pg_namespace n ON n.oid = c.relnamespace
            WHERE c.relkind IN ('r', 'v')
                AND n.nspname NOT IN ('pg_catalog', 'pg_toast')
                AND pg_catalog.pg_table_is_visible(c.oid); args=None
(0.001) SELECT "django_migrations"."app", "django_migrations"."name" FROM "django_migrations"; args=()
(0.002) 
            SELECT c.relname, c.relkind
            FROM pg_catalog.pg_class c
            LEFT JOIN pg_catalog.pg_namespace n ON n.oid = c.relnamespace
            WHERE c.relkind IN ('r', 'v')
                AND n.nspname NOT IN ('pg_catalog', 'pg_toast')
                AND pg_catalog.pg_table_is_visible(c.oid); args=None
(0.001) SELECT "django_migrations"."app", "django_migrations"."name" FROM "django_migrations"; args=()
(0.002) 
            SELECT c.relname, c.relkind
            FROM pg_catalog.pg_class c
            LEFT JOIN pg_catalog.pg_namespace n ON n.oid = c.relnamespace
            WHERE c.relkind IN ('r', 'v')
                AND n.nspname NOT IN ('pg_catalog', 'pg_toast')
                AND pg_catalog.pg_table_is_visible(c.oid); args=None
(0.001) SELECT "django_migrations"."app", "django_migrations"."name" FROM "django_migrations"; args=()
Internal Server Error: /api/user-process-history/
Traceback (most recent call last):
  File "/Library/WebServer/Documents/profiles-rest-api/profiles_api/lib/python3.6/site-packages/django/core/handlers/exception.py", line 41, in inner
    response = get_response(request)
  File "/Library/WebServer/Documents/profiles-rest-api/profiles_api/lib/python3.6/site-packages/django/core/handlers/base.py", line 187, in _get_response
    response = self.process_exception_by_middleware(e, request)
  File "/Library/WebServer/Documents/profiles-rest-api/profiles_api/lib/python3.6/site-packages/django/core/handlers/base.py", line 185, in _get_response
    response = wrapped_callback(request, *callback_args, **callback_kwargs)
  File "/Library/WebServer/Documents/profiles-rest-api/profiles_api/lib/python3.6/site-packages/django/views/decorators/csrf.py", line 58, in wrapped_view
    return view_func(*args, **kwargs)
  File "/Library/WebServer/Documents/profiles-rest-api/profiles_api/lib/python3.6/site-packages/rest_framework/viewsets.py", line 83, in view
    return self.dispatch(request, *args, **kwargs)
  File "/Library/WebServer/Documents/profiles-rest-api/profiles_api/lib/python3.6/site-packages/rest_framework/views.py", line 483, in dispatch
    response = self.handle_exception(exc)
  File "/Library/WebServer/Documents/profiles-rest-api/profiles_api/lib/python3.6/site-packages/rest_framework/views.py", line 443, in handle_exception
    self.raise_uncaught_exception(exc)
  File "/Library/WebServer/Documents/profiles-rest-api/profiles_api/lib/python3.6/site-packages/rest_framework/views.py", line 480, in dispatch
    response = handler(request, *args, **kwargs)
  File "/Library/WebServer/Documents/profiles-rest-api/profiles_api/lib/python3.6/site-packages/rest_framework/mixins.py", line 40, in list
    queryset = self.filter_queryset(self.get_queryset())
  File "/Library/WebServer/Documents/profiles-rest-api/src/profiles_project/profiles_api/views.py", line 158, in get_queryset
    return models.UserProcessHistory.objects.filter(user_profile=user)
  File "/Library/WebServer/Documents/profiles-rest-api/profiles_api/lib/python3.6/site-packages/django/db/models/manager.py", line 85, in manager_method
    return getattr(self.get_queryset(), name)(*args, **kwargs)
  File "/Library/WebServer/Documents/profiles-rest-api/profiles_api/lib/python3.6/site-packages/django/db/models/query.py", line 781, in filter
    return self._filter_or_exclude(False, *args, **kwargs)
  File "/Library/WebServer/Documents/profiles-rest-api/profiles_api/lib/python3.6/site-packages/django/db/models/query.py", line 799, in _filter_or_exclude
    clone.query.add_q(Q(*args, **kwargs))
  File "/Library/WebServer/Documents/profiles-rest-api/profiles_api/lib/python3.6/site-packages/django/db/models/sql/query.py", line 1260, in add_q
    clause, _ = self._add_q(q_object, self.used_aliases)
  File "/Library/WebServer/Documents/profiles-rest-api/profiles_api/lib/python3.6/site-packages/django/db/models/sql/query.py", line 1286, in _add_q
    allow_joins=allow_joins, split_subq=split_subq,
  File "/Library/WebServer/Documents/profiles-rest-api/profiles_api/lib/python3.6/site-packages/django/db/models/sql/query.py", line 1216, in build_filter
    condition = lookup_class(lhs, value)
  File "/Library/WebServer/Documents/profiles-rest-api/profiles_api/lib/python3.6/site-packages/django/db/models/lookups.py", line 24, in __init__
    self.rhs = self.get_prep_lookup()
  File "/Library/WebServer/Documents/profiles-rest-api/profiles_api/lib/python3.6/site-packages/django/db/models/fields/related_lookups.py", line 110, in get_prep_lookup
    self.rhs = target_field.get_prep_value(self.rhs)
  File "/Library/WebServer/Documents/profiles-rest-api/profiles_api/lib/python3.6/site-packages/django/db/models/fields/__init__.py", line 962, in get_prep_value
    return int(value)
TypeError: int() argument must be a string, a bytes-like object or a number, not 'AnonymousUser'
(0.001) SELECT "profiles_api_userprocesshistory"."id", "profiles_api_userprocesshistory"."user_profile_id", "profiles_api_userprocesshistory"."description", "profiles_api_userprocesshistory"."last_mod", "profiles_api_userprocesshistory"."remaining_storage", "profiles_api_userprocesshistory"."status" FROM "profiles_api_userprocesshistory" LIMIT 21; args=()
(0.000) SELECT "profiles_api_userprocesshistory"."id", "profiles_api_userprocesshistory"."user_profile_id", "profiles_api_userprocesshistory"."description", "profiles_api_userprocesshistory"."last_mod", "profiles_api_userprocesshistory"."remaining_storage", "profiles_api_userprocesshistory"."status" FROM "profiles_api_userprocesshistory" LIMIT 21; args=()
(0.000) SELECT "profiles_api_userprocesshistory"."id", "profiles_api_userprocesshistory"."user_profile_id", "profiles_api_userprocesshistory"."description", "profiles_api_userprocesshistory"."last_mod", "profiles_api_userprocesshistory"."remaining_storage", "profiles_api_userprocesshistory"."status" FROM "profiles_api_userprocesshistory" LIMIT 21; args=()
"GET /api/user-process-history/ HTTP/1.1" 500 135926
(0.003) 
            SELECT c.relname, c.relkind
            FROM pg_catalog.pg_class c
            LEFT JOIN pg_catalog.pg_namespace n ON n.oid = c.relnamespace
            WHERE c.relkind IN ('r', 'v')
                AND n.nspname NOT IN ('pg_catalog', 'pg_toast')
                AND pg_catalog.pg_table_is_visible(c.oid); args=None
(0.001) SELECT "django_migrations"."app", "django_migrations"."name" FROM "django_migrations"; args=()
Internal Server Error: /api/user-process-history/
Traceback (most recent call last):
  File "/Library/WebServer/Documents/profiles-rest-api/profiles_api/lib/python3.6/site-packages/django/core/handlers/exception.py", line 41, in inner
    response = get_response(request)
  File "/Library/WebServer/Documents/profiles-rest-api/profiles_api/lib/python3.6/site-packages/django/core/handlers/base.py", line 187, in _get_response
    response = self.process_exception_by_middleware(e, request)
  File "/Library/WebServer/Documents/profiles-rest-api/profiles_api/lib/python3.6/site-packages/django/core/handlers/base.py", line 185, in _get_response
    response = wrapped_callback(request, *callback_args, **callback_kwargs)
  File "/Library/WebServer/Documents/profiles-rest-api/profiles_api/lib/python3.6/site-packages/django/views/decorators/csrf.py", line 58, in wrapped_view
    return view_func(*args, **kwargs)
  File "/Library/WebServer/Documents/profiles-rest-api/profiles_api/lib/python3.6/site-packages/rest_framework/viewsets.py", line 83, in view
    return self.dispatch(request, *args, **kwargs)
  File "/Library/WebServer/Documents/profiles-rest-api/profiles_api/lib/python3.6/site-packages/rest_framework/views.py", line 483, in dispatch
    response = self.handle_exception(exc)
  File "/Library/WebServer/Documents/profiles-rest-api/profiles_api/lib/python3.6/site-packages/rest_framework/views.py", line 443, in handle_exception
    self.raise_uncaught_exception(exc)
  File "/Library/WebServer/Documents/profiles-rest-api/profiles_api/lib/python3.6/site-packages/rest_framework/views.py", line 480, in dispatch
    response = handler(request, *args, **kwargs)
  File "/Library/WebServer/Documents/profiles-rest-api/profiles_api/lib/python3.6/site-packages/rest_framework/mixins.py", line 40, in list
    queryset = self.filter_queryset(self.get_queryset())
  File "/Library/WebServer/Documents/profiles-rest-api/src/profiles_project/profiles_api/views.py", line 160, in get_queryset
    return queryset
NameError: name 'queryset' is not defined
"GET /api/user-process-history/ HTTP/1.1" 500 90817
(0.005) 
            SELECT c.relname, c.relkind
            FROM pg_catalog.pg_class c
            LEFT JOIN pg_catalog.pg_namespace n ON n.oid = c.relnamespace
            WHERE c.relkind IN ('r', 'v')
                AND n.nspname NOT IN ('pg_catalog', 'pg_toast')
                AND pg_catalog.pg_table_is_visible(c.oid); args=None
(0.001) SELECT "django_migrations"."app", "django_migrations"."name" FROM "django_migrations"; args=()
Internal Server Error: /api/user-process-history/
Traceback (most recent call last):
  File "/Library/WebServer/Documents/profiles-rest-api/profiles_api/lib/python3.6/site-packages/django/core/handlers/exception.py", line 41, in inner
    response = get_response(request)
  File "/Library/WebServer/Documents/profiles-rest-api/profiles_api/lib/python3.6/site-packages/django/core/handlers/base.py", line 187, in _get_response
    response = self.process_exception_by_middleware(e, request)
  File "/Library/WebServer/Documents/profiles-rest-api/profiles_api/lib/python3.6/site-packages/django/core/handlers/base.py", line 185, in _get_response
    response = wrapped_callback(request, *callback_args, **callback_kwargs)
  File "/Library/WebServer/Documents/profiles-rest-api/profiles_api/lib/python3.6/site-packages/django/views/decorators/csrf.py", line 58, in wrapped_view
    return view_func(*args, **kwargs)
  File "/Library/WebServer/Documents/profiles-rest-api/profiles_api/lib/python3.6/site-packages/rest_framework/viewsets.py", line 83, in view
    return self.dispatch(request, *args, **kwargs)
  File "/Library/WebServer/Documents/profiles-rest-api/profiles_api/lib/python3.6/site-packages/rest_framework/views.py", line 483, in dispatch
    response = self.handle_exception(exc)
  File "/Library/WebServer/Documents/profiles-rest-api/profiles_api/lib/python3.6/site-packages/rest_framework/views.py", line 443, in handle_exception
    self.raise_uncaught_exception(exc)
  File "/Library/WebServer/Documents/profiles-rest-api/profiles_api/lib/python3.6/site-packages/rest_framework/views.py", line 480, in dispatch
    response = handler(request, *args, **kwargs)
  File "/Library/WebServer/Documents/profiles-rest-api/profiles_api/lib/python3.6/site-packages/rest_framework/mixins.py", line 40, in list
    queryset = self.filter_queryset(self.get_queryset())
  File "/Library/WebServer/Documents/profiles-rest-api/src/profiles_project/profiles_api/views.py", line 158, in get_queryset
    return models.UserProcessHistory.objects.filter(user_profile=user)
  File "/Library/WebServer/Documents/profiles-rest-api/profiles_api/lib/python3.6/site-packages/django/db/models/manager.py", line 85, in manager_method
    return getattr(self.get_queryset(), name)(*args, **kwargs)
  File "/Library/WebServer/Documents/profiles-rest-api/profiles_api/lib/python3.6/site-packages/django/db/models/query.py", line 781, in filter
    return self._filter_or_exclude(False, *args, **kwargs)
  File "/Library/WebServer/Documents/profiles-rest-api/profiles_api/lib/python3.6/site-packages/django/db/models/query.py", line 799, in _filter_or_exclude
    clone.query.add_q(Q(*args, **kwargs))
  File "/Library/WebServer/Documents/profiles-rest-api/profiles_api/lib/python3.6/site-packages/django/db/models/sql/query.py", line 1260, in add_q
    clause, _ = self._add_q(q_object, self.used_aliases)
  File "/Library/WebServer/Documents/profiles-rest-api/profiles_api/lib/python3.6/site-packages/django/db/models/sql/query.py", line 1286, in _add_q
    allow_joins=allow_joins, split_subq=split_subq,
  File "/Library/WebServer/Documents/profiles-rest-api/profiles_api/lib/python3.6/site-packages/django/db/models/sql/query.py", line 1216, in build_filter
    condition = lookup_class(lhs, value)
  File "/Library/WebServer/Documents/profiles-rest-api/profiles_api/lib/python3.6/site-packages/django/db/models/lookups.py", line 24, in __init__
    self.rhs = self.get_prep_lookup()
  File "/Library/WebServer/Documents/profiles-rest-api/profiles_api/lib/python3.6/site-packages/django/db/models/fields/related_lookups.py", line 110, in get_prep_lookup
    self.rhs = target_field.get_prep_value(self.rhs)
  File "/Library/WebServer/Documents/profiles-rest-api/profiles_api/lib/python3.6/site-packages/django/db/models/fields/__init__.py", line 962, in get_prep_value
    return int(value)
TypeError: int() argument must be a string, a bytes-like object or a number, not 'AnonymousUser'
(0.001) SELECT "profiles_api_userprocesshistory"."id", "profiles_api_userprocesshistory"."user_profile_id", "profiles_api_userprocesshistory"."description", "profiles_api_userprocesshistory"."last_mod", "profiles_api_userprocesshistory"."remaining_storage", "profiles_api_userprocesshistory"."status" FROM "profiles_api_userprocesshistory" LIMIT 21; args=()
(0.000) SELECT "profiles_api_userprocesshistory"."id", "profiles_api_userprocesshistory"."user_profile_id", "profiles_api_userprocesshistory"."description", "profiles_api_userprocesshistory"."last_mod", "profiles_api_userprocesshistory"."remaining_storage", "profiles_api_userprocesshistory"."status" FROM "profiles_api_userprocesshistory" LIMIT 21; args=()
(0.000) SELECT "profiles_api_userprocesshistory"."id", "profiles_api_userprocesshistory"."user_profile_id", "profiles_api_userprocesshistory"."description", "profiles_api_userprocesshistory"."last_mod", "profiles_api_userprocesshistory"."remaining_storage", "profiles_api_userprocesshistory"."status" FROM "profiles_api_userprocesshistory" LIMIT 21; args=()
"GET /api/user-process-history/ HTTP/1.1" 500 135926
(0.002) SELECT "authtoken_token"."key", "authtoken_token"."user_id", "authtoken_token"."created", "profiles_api_userprofile"."id", "profiles_api_userprofile"."password", "profiles_api_userprofile"."last_login", "profiles_api_userprofile"."is_superuser", "profiles_api_userprofile"."email", "profiles_api_userprofile"."name", "profiles_api_userprofile"."lastname", "profiles_api_userprofile"."is_active", "profiles_api_userprofile"."is_staff", "profiles_api_userprofile"."country", "profiles_api_userprofile"."phone", "profiles_api_userprofile"."url_image", "profiles_api_userprofile"."state" FROM "authtoken_token" INNER JOIN "profiles_api_userprofile" ON ("authtoken_token"."user_id" = "profiles_api_userprofile"."id") WHERE "authtoken_token"."key" = '6412fe01d4f83677bafe2261d6dad0cc7405562b'; args=('6412fe01d4f83677bafe2261d6dad0cc7405562b',)
(0.001) SELECT "profiles_api_userprocesshistory"."id", "profiles_api_userprocesshistory"."user_profile_id", "profiles_api_userprocesshistory"."description", "profiles_api_userprocesshistory"."last_mod", "profiles_api_userprocesshistory"."remaining_storage", "profiles_api_userprocesshistory"."status" FROM "profiles_api_userprocesshistory" WHERE "profiles_api_userprocesshistory"."user_profile_id" = 5; args=(5,)
Exception while resolving variable 'hide_label' in template 'rest_framework/horizontal/select.html'.
Traceback (most recent call last):
  File "/Library/WebServer/Documents/profiles-rest-api/profiles_api/lib/python3.6/site-packages/django/template/base.py", line 882, in _resolve_lookup
    current = current[bit]
KeyError: 'hide_label'

During handling of the above exception, another exception occurred:

Traceback (most recent call last):
  File "/Library/WebServer/Documents/profiles-rest-api/profiles_api/lib/python3.6/site-packages/django/template/base.py", line 890, in _resolve_lookup
    current = getattr(current, bit)
AttributeError: 'dict' object has no attribute 'hide_label'

During handling of the above exception, another exception occurred:

Traceback (most recent call last):
  File "/Library/WebServer/Documents/profiles-rest-api/profiles_api/lib/python3.6/site-packages/django/template/base.py", line 896, in _resolve_lookup
    current = current[int(bit)]
ValueError: invalid literal for int() with base 10: 'hide_label'

During handling of the above exception, another exception occurred:

Traceback (most recent call last):
  File "/Library/WebServer/Documents/profiles-rest-api/profiles_api/lib/python3.6/site-packages/django/template/base.py", line 903, in _resolve_lookup
    (bit, current))  # missing attribute
django.template.base.VariableDoesNotExist: Failed lookup for key [hide_label] in "{'base_template': 'select.html', 'template_pack': 'rest_framework/horizontal', 'renderer': <rest_framework.renderers.HTMLFormRenderer object at 0x103105978>}"
Exception while resolving variable 'allow_blank' in template 'rest_framework/horizontal/select.html'.
Traceback (most recent call last):
  File "/Library/WebServer/Documents/profiles-rest-api/profiles_api/lib/python3.6/site-packages/django/template/base.py", line 882, in _resolve_lookup
    current = current[bit]
TypeError: 'BoundField' object is not subscriptable

During handling of the above exception, another exception occurred:

Traceback (most recent call last):
  File "/Library/WebServer/Documents/profiles-rest-api/profiles_api/lib/python3.6/site-packages/django/template/base.py", line 890, in _resolve_lookup
    current = getattr(current, bit)
  File "/Library/WebServer/Documents/profiles-rest-api/profiles_api/lib/python3.6/site-packages/rest_framework/utils/serializer_helpers.py", line 69, in __getattr__
    return getattr(self._field, attr_name)
AttributeError: 'PrimaryKeyRelatedField' object has no attribute 'allow_blank'

During handling of the above exception, another exception occurred:

Traceback (most recent call last):
  File "/Library/WebServer/Documents/profiles-rest-api/profiles_api/lib/python3.6/site-packages/django/template/base.py", line 896, in _resolve_lookup
    current = current[int(bit)]
ValueError: invalid literal for int() with base 10: 'allow_blank'

During handling of the above exception, another exception occurred:

Traceback (most recent call last):
  File "/Library/WebServer/Documents/profiles-rest-api/profiles_api/lib/python3.6/site-packages/django/template/base.py", line 903, in _resolve_lookup
    (bit, current))  # missing attribute
django.template.base.VariableDoesNotExist: Failed lookup for key [allow_blank] in '<BoundField value= errors=None>'
(0.001) SELECT "profiles_api_userprofile"."id", "profiles_api_userprofile"."password", "profiles_api_userprofile"."last_login", "profiles_api_userprofile"."is_superuser", "profiles_api_userprofile"."email", "profiles_api_userprofile"."name", "profiles_api_userprofile"."lastname", "profiles_api_userprofile"."is_active", "profiles_api_userprofile"."is_staff", "profiles_api_userprofile"."country", "profiles_api_userprofile"."phone", "profiles_api_userprofile"."url_image", "profiles_api_userprofile"."state" FROM "profiles_api_userprofile" LIMIT 1000; args=()
Exception while resolving variable 'hide_label' in template 'rest_framework/horizontal/input.html'.
Traceback (most recent call last):
  File "/Library/WebServer/Documents/profiles-rest-api/profiles_api/lib/python3.6/site-packages/django/template/base.py", line 882, in _resolve_lookup
    current = current[bit]
KeyError: 'hide_label'

During handling of the above exception, another exception occurred:

Traceback (most recent call last):
  File "/Library/WebServer/Documents/profiles-rest-api/profiles_api/lib/python3.6/site-packages/django/template/base.py", line 890, in _resolve_lookup
    current = getattr(current, bit)
AttributeError: 'dict' object has no attribute 'hide_label'

During handling of the above exception, another exception occurred:

Traceback (most recent call last):
  File "/Library/WebServer/Documents/profiles-rest-api/profiles_api/lib/python3.6/site-packages/django/template/base.py", line 896, in _resolve_lookup
    current = current[int(bit)]
ValueError: invalid literal for int() with base 10: 'hide_label'

During handling of the above exception, another exception occurred:

Traceback (most recent call last):
  File "/Library/WebServer/Documents/profiles-rest-api/profiles_api/lib/python3.6/site-packages/django/template/base.py", line 903, in _resolve_lookup
    (bit, current))  # missing attribute
django.template.base.VariableDoesNotExist: Failed lookup for key [hide_label] in "{'base_template': 'input.html', 'input_type': 'text', 'template_pack': 'rest_framework/horizontal', 'renderer': <rest_framework.renderers.HTMLFormRenderer object at 0x103105978>}"
Exception while resolving variable 'placeholder' in template 'rest_framework/horizontal/input.html'.
Traceback (most recent call last):
  File "/Library/WebServer/Documents/profiles-rest-api/profiles_api/lib/python3.6/site-packages/django/template/base.py", line 882, in _resolve_lookup
    current = current[bit]
KeyError: 'placeholder'

During handling of the above exception, another exception occurred:

Traceback (most recent call last):
  File "/Library/WebServer/Documents/profiles-rest-api/profiles_api/lib/python3.6/site-packages/django/template/base.py", line 890, in _resolve_lookup
    current = getattr(current, bit)
AttributeError: 'dict' object has no attribute 'placeholder'

During handling of the above exception, another exception occurred:

Traceback (most recent call last):
  File "/Library/WebServer/Documents/profiles-rest-api/profiles_api/lib/python3.6/site-packages/django/template/base.py", line 896, in _resolve_lookup
    current = current[int(bit)]
ValueError: invalid literal for int() with base 10: 'placeholder'

During handling of the above exception, another exception occurred:

Traceback (most recent call last):
  File "/Library/WebServer/Documents/profiles-rest-api/profiles_api/lib/python3.6/site-packages/django/template/base.py", line 903, in _resolve_lookup
    (bit, current))  # missing attribute
django.template.base.VariableDoesNotExist: Failed lookup for key [placeholder] in "{'base_template': 'input.html', 'input_type': 'text', 'template_pack': 'rest_framework/horizontal', 'renderer': <rest_framework.renderers.HTMLFormRenderer object at 0x103105978>}"
Exception while resolving variable 'autofocus' in template 'rest_framework/horizontal/input.html'.
Traceback (most recent call last):
  File "/Library/WebServer/Documents/profiles-rest-api/profiles_api/lib/python3.6/site-packages/django/template/base.py", line 882, in _resolve_lookup
    current = current[bit]
KeyError: 'autofocus'

During handling of the above exception, another exception occurred:

Traceback (most recent call last):
  File "/Library/WebServer/Documents/profiles-rest-api/profiles_api/lib/python3.6/site-packages/django/template/base.py", line 890, in _resolve_lookup
    current = getattr(current, bit)
AttributeError: 'dict' object has no attribute 'autofocus'

During handling of the above exception, another exception occurred:

Traceback (most recent call last):
  File "/Library/WebServer/Documents/profiles-rest-api/profiles_api/lib/python3.6/site-packages/django/template/base.py", line 896, in _resolve_lookup
    current = current[int(bit)]
ValueError: invalid literal for int() with base 10: 'autofocus'

During handling of the above exception, another exception occurred:

Traceback (most recent call last):
  File "/Library/WebServer/Documents/profiles-rest-api/profiles_api/lib/python3.6/site-packages/django/template/base.py", line 903, in _resolve_lookup
    (bit, current))  # missing attribute
django.template.base.VariableDoesNotExist: Failed lookup for key [autofocus] in "{'base_template': 'input.html', 'input_type': 'text', 'template_pack': 'rest_framework/horizontal', 'renderer': <rest_framework.renderers.HTMLFormRenderer object at 0x103105978>}"
Exception while resolving variable 'hide_label' in template 'rest_framework/horizontal/input.html'.
Traceback (most recent call last):
  File "/Library/WebServer/Documents/profiles-rest-api/profiles_api/lib/python3.6/site-packages/django/template/base.py", line 882, in _resolve_lookup
    current = current[bit]
KeyError: 'hide_label'

During handling of the above exception, another exception occurred:

Traceback (most recent call last):
  File "/Library/WebServer/Documents/profiles-rest-api/profiles_api/lib/python3.6/site-packages/django/template/base.py", line 890, in _resolve_lookup
    current = getattr(current, bit)
AttributeError: 'dict' object has no attribute 'hide_label'

During handling of the above exception, another exception occurred:

Traceback (most recent call last):
  File "/Library/WebServer/Documents/profiles-rest-api/profiles_api/lib/python3.6/site-packages/django/template/base.py", line 896, in _resolve_lookup
    current = current[int(bit)]
ValueError: invalid literal for int() with base 10: 'hide_label'

During handling of the above exception, another exception occurred:

Traceback (most recent call last):
  File "/Library/WebServer/Documents/profiles-rest-api/profiles_api/lib/python3.6/site-packages/django/template/base.py", line 903, in _resolve_lookup
    (bit, current))  # missing attribute
django.template.base.VariableDoesNotExist: Failed lookup for key [hide_label] in "{'base_template': 'input.html', 'input_type': 'text', 'template_pack': 'rest_framework/horizontal', 'renderer': <rest_framework.renderers.HTMLFormRenderer object at 0x103105978>}"
Exception while resolving variable 'placeholder' in template 'rest_framework/horizontal/input.html'.
Traceback (most recent call last):
  File "/Library/WebServer/Documents/profiles-rest-api/profiles_api/lib/python3.6/site-packages/django/template/base.py", line 882, in _resolve_lookup
    current = current[bit]
KeyError: 'placeholder'

During handling of the above exception, another exception occurred:

Traceback (most recent call last):
  File "/Library/WebServer/Documents/profiles-rest-api/profiles_api/lib/python3.6/site-packages/django/template/base.py", line 890, in _resolve_lookup
    current = getattr(current, bit)
AttributeError: 'dict' object has no attribute 'placeholder'

During handling of the above exception, another exception occurred:

Traceback (most recent call last):
  File "/Library/WebServer/Documents/profiles-rest-api/profiles_api/lib/python3.6/site-packages/django/template/base.py", line 896, in _resolve_lookup
    current = current[int(bit)]
ValueError: invalid literal for int() with base 10: 'placeholder'

During handling of the above exception, another exception occurred:

Traceback (most recent call last):
  File "/Library/WebServer/Documents/profiles-rest-api/profiles_api/lib/python3.6/site-packages/django/template/base.py", line 903, in _resolve_lookup
    (bit, current))  # missing attribute
django.template.base.VariableDoesNotExist: Failed lookup for key [placeholder] in "{'base_template': 'input.html', 'input_type': 'text', 'template_pack': 'rest_framework/horizontal', 'renderer': <rest_framework.renderers.HTMLFormRenderer object at 0x103105978>}"
Exception while resolving variable 'autofocus' in template 'rest_framework/horizontal/input.html'.
Traceback (most recent call last):
  File "/Library/WebServer/Documents/profiles-rest-api/profiles_api/lib/python3.6/site-packages/django/template/base.py", line 882, in _resolve_lookup
    current = current[bit]
KeyError: 'autofocus'

During handling of the above exception, another exception occurred:

Traceback (most recent call last):
  File "/Library/WebServer/Documents/profiles-rest-api/profiles_api/lib/python3.6/site-packages/django/template/base.py", line 890, in _resolve_lookup
    current = getattr(current, bit)
AttributeError: 'dict' object has no attribute 'autofocus'

During handling of the above exception, another exception occurred:

Traceback (most recent call last):
  File "/Library/WebServer/Documents/profiles-rest-api/profiles_api/lib/python3.6/site-packages/django/template/base.py", line 896, in _resolve_lookup
    current = current[int(bit)]
ValueError: invalid literal for int() with base 10: 'autofocus'

During handling of the above exception, another exception occurred:

Traceback (most recent call last):
  File "/Library/WebServer/Documents/profiles-rest-api/profiles_api/lib/python3.6/site-packages/django/template/base.py", line 903, in _resolve_lookup
    (bit, current))  # missing attribute
django.template.base.VariableDoesNotExist: Failed lookup for key [autofocus] in "{'base_template': 'input.html', 'input_type': 'text', 'template_pack': 'rest_framework/horizontal', 'renderer': <rest_framework.renderers.HTMLFormRenderer object at 0x103105978>}"
Exception while resolving variable 'hide_label' in template 'rest_framework/horizontal/input.html'.
Traceback (most recent call last):
  File "/Library/WebServer/Documents/profiles-rest-api/profiles_api/lib/python3.6/site-packages/django/template/base.py", line 882, in _resolve_lookup
    current = current[bit]
KeyError: 'hide_label'

During handling of the above exception, another exception occurred:

Traceback (most recent call last):
  File "/Library/WebServer/Documents/profiles-rest-api/profiles_api/lib/python3.6/site-packages/django/template/base.py", line 890, in _resolve_lookup
    current = getattr(current, bit)
AttributeError: 'dict' object has no attribute 'hide_label'

During handling of the above exception, another exception occurred:

Traceback (most recent call last):
  File "/Library/WebServer/Documents/profiles-rest-api/profiles_api/lib/python3.6/site-packages/django/template/base.py", line 896, in _resolve_lookup
    current = current[int(bit)]
ValueError: invalid literal for int() with base 10: 'hide_label'

During handling of the above exception, another exception occurred:

Traceback (most recent call last):
  File "/Library/WebServer/Documents/profiles-rest-api/profiles_api/lib/python3.6/site-packages/django/template/base.py", line 903, in _resolve_lookup
    (bit, current))  # missing attribute
django.template.base.VariableDoesNotExist: Failed lookup for key [hide_label] in "{'base_template': 'input.html', 'input_type': 'number', 'template_pack': 'rest_framework/horizontal', 'renderer': <rest_framework.renderers.HTMLFormRenderer object at 0x103105978>}"
Exception while resolving variable 'placeholder' in template 'rest_framework/horizontal/input.html'.
Traceback (most recent call last):
  File "/Library/WebServer/Documents/profiles-rest-api/profiles_api/lib/python3.6/site-packages/django/template/base.py", line 882, in _resolve_lookup
    current = current[bit]
KeyError: 'placeholder'

During handling of the above exception, another exception occurred:

Traceback (most recent call last):
  File "/Library/WebServer/Documents/profiles-rest-api/profiles_api/lib/python3.6/site-packages/django/template/base.py", line 890, in _resolve_lookup
    current = getattr(current, bit)
AttributeError: 'dict' object has no attribute 'placeholder'

During handling of the above exception, another exception occurred:

Traceback (most recent call last):
  File "/Library/WebServer/Documents/profiles-rest-api/profiles_api/lib/python3.6/site-packages/django/template/base.py", line 896, in _resolve_lookup
    current = current[int(bit)]
ValueError: invalid literal for int() with base 10: 'placeholder'

During handling of the above exception, another exception occurred:

Traceback (most recent call last):
  File "/Library/WebServer/Documents/profiles-rest-api/profiles_api/lib/python3.6/site-packages/django/template/base.py", line 903, in _resolve_lookup
    (bit, current))  # missing attribute
django.template.base.VariableDoesNotExist: Failed lookup for key [placeholder] in "{'base_template': 'input.html', 'input_type': 'number', 'template_pack': 'rest_framework/horizontal', 'renderer': <rest_framework.renderers.HTMLFormRenderer object at 0x103105978>}"
Exception while resolving variable 'autofocus' in template 'rest_framework/horizontal/input.html'.
Traceback (most recent call last):
  File "/Library/WebServer/Documents/profiles-rest-api/profiles_api/lib/python3.6/site-packages/django/template/base.py", line 882, in _resolve_lookup
    current = current[bit]
KeyError: 'autofocus'

During handling of the above exception, another exception occurred:

Traceback (most recent call last):
  File "/Library/WebServer/Documents/profiles-rest-api/profiles_api/lib/python3.6/site-packages/django/template/base.py", line 890, in _resolve_lookup
    current = getattr(current, bit)
AttributeError: 'dict' object has no attribute 'autofocus'

During handling of the above exception, another exception occurred:

Traceback (most recent call last):
  File "/Library/WebServer/Documents/profiles-rest-api/profiles_api/lib/python3.6/site-packages/django/template/base.py", line 896, in _resolve_lookup
    current = current[int(bit)]
ValueError: invalid literal for int() with base 10: 'autofocus'

During handling of the above exception, another exception occurred:

Traceback (most recent call last):
  File "/Library/WebServer/Documents/profiles-rest-api/profiles_api/lib/python3.6/site-packages/django/template/base.py", line 903, in _resolve_lookup
    (bit, current))  # missing attribute
django.template.base.VariableDoesNotExist: Failed lookup for key [autofocus] in "{'base_template': 'input.html', 'input_type': 'number', 'template_pack': 'rest_framework/horizontal', 'renderer': <rest_framework.renderers.HTMLFormRenderer object at 0x103105978>}"
"GET /api/user-process-history/ HTTP/1.1" 200 9985
"GET /static/rest_framework/css/bootstrap.min.css HTTP/1.1" 304 0
"GET /static/rest_framework/css/bootstrap-tweaks.css HTTP/1.1" 304 0
"GET /static/rest_framework/css/prettify.css HTTP/1.1" 304 0
"GET /static/rest_framework/css/default.css HTTP/1.1" 304 0
"GET /static/rest_framework/js/jquery-1.12.4.min.js HTTP/1.1" 304 0
"GET /static/rest_framework/js/ajax-form.js HTTP/1.1" 304 0
"GET /static/rest_framework/js/csrf.js HTTP/1.1" 304 0
"GET /static/rest_framework/js/bootstrap.min.js HTTP/1.1" 304 0
"GET /static/rest_framework/js/default.js HTTP/1.1" 304 0
"GET /static/rest_framework/js/prettify-min.js HTTP/1.1" 304 0
"GET /static/rest_framework/img/grid.png HTTP/1.1" 304 0
(0.002) SELECT "authtoken_token"."key", "authtoken_token"."user_id", "authtoken_token"."created", "profiles_api_userprofile"."id", "profiles_api_userprofile"."password", "profiles_api_userprofile"."last_login", "profiles_api_userprofile"."is_superuser", "profiles_api_userprofile"."email", "profiles_api_userprofile"."name", "profiles_api_userprofile"."lastname", "profiles_api_userprofile"."is_active", "profiles_api_userprofile"."is_staff", "profiles_api_userprofile"."country", "profiles_api_userprofile"."phone", "profiles_api_userprofile"."url_image", "profiles_api_userprofile"."state" FROM "authtoken_token" INNER JOIN "profiles_api_userprofile" ON ("authtoken_token"."user_id" = "profiles_api_userprofile"."id") WHERE "authtoken_token"."key" = '6412fe01d4f83677bafe2261d6dad0cc7405562b'; args=('6412fe01d4f83677bafe2261d6dad0cc7405562b',)
(0.001) SELECT "profiles_api_userprocesshistory"."id", "profiles_api_userprocesshistory"."user_profile_id", "profiles_api_userprocesshistory"."description", "profiles_api_userprocesshistory"."last_mod", "profiles_api_userprocesshistory"."remaining_storage", "profiles_api_userprocesshistory"."status" FROM "profiles_api_userprocesshistory" WHERE "profiles_api_userprocesshistory"."user_profile_id" = 5; args=(5,)
Exception while resolving variable 'hide_label' in template 'rest_framework/horizontal/select.html'.
Traceback (most recent call last):
  File "/Library/WebServer/Documents/profiles-rest-api/profiles_api/lib/python3.6/site-packages/django/template/base.py", line 882, in _resolve_lookup
    current = current[bit]
KeyError: 'hide_label'

During handling of the above exception, another exception occurred:

Traceback (most recent call last):
  File "/Library/WebServer/Documents/profiles-rest-api/profiles_api/lib/python3.6/site-packages/django/template/base.py", line 890, in _resolve_lookup
    current = getattr(current, bit)
AttributeError: 'dict' object has no attribute 'hide_label'

During handling of the above exception, another exception occurred:

Traceback (most recent call last):
  File "/Library/WebServer/Documents/profiles-rest-api/profiles_api/lib/python3.6/site-packages/django/template/base.py", line 896, in _resolve_lookup
    current = current[int(bit)]
ValueError: invalid literal for int() with base 10: 'hide_label'

During handling of the above exception, another exception occurred:

Traceback (most recent call last):
  File "/Library/WebServer/Documents/profiles-rest-api/profiles_api/lib/python3.6/site-packages/django/template/base.py", line 903, in _resolve_lookup
    (bit, current))  # missing attribute
django.template.base.VariableDoesNotExist: Failed lookup for key [hide_label] in "{'base_template': 'select.html', 'template_pack': 'rest_framework/horizontal', 'renderer': <rest_framework.renderers.HTMLFormRenderer object at 0x1030d5e10>}"
Exception while resolving variable 'allow_blank' in template 'rest_framework/horizontal/select.html'.
Traceback (most recent call last):
  File "/Library/WebServer/Documents/profiles-rest-api/profiles_api/lib/python3.6/site-packages/django/template/base.py", line 882, in _resolve_lookup
    current = current[bit]
TypeError: 'BoundField' object is not subscriptable

During handling of the above exception, another exception occurred:

Traceback (most recent call last):
  File "/Library/WebServer/Documents/profiles-rest-api/profiles_api/lib/python3.6/site-packages/django/template/base.py", line 890, in _resolve_lookup
    current = getattr(current, bit)
  File "/Library/WebServer/Documents/profiles-rest-api/profiles_api/lib/python3.6/site-packages/rest_framework/utils/serializer_helpers.py", line 69, in __getattr__
    return getattr(self._field, attr_name)
AttributeError: 'PrimaryKeyRelatedField' object has no attribute 'allow_blank'

During handling of the above exception, another exception occurred:

Traceback (most recent call last):
  File "/Library/WebServer/Documents/profiles-rest-api/profiles_api/lib/python3.6/site-packages/django/template/base.py", line 896, in _resolve_lookup
    current = current[int(bit)]
ValueError: invalid literal for int() with base 10: 'allow_blank'

During handling of the above exception, another exception occurred:

Traceback (most recent call last):
  File "/Library/WebServer/Documents/profiles-rest-api/profiles_api/lib/python3.6/site-packages/django/template/base.py", line 903, in _resolve_lookup
    (bit, current))  # missing attribute
django.template.base.VariableDoesNotExist: Failed lookup for key [allow_blank] in '<BoundField value= errors=None>'
(0.000) SELECT "profiles_api_userprofile"."id", "profiles_api_userprofile"."password", "profiles_api_userprofile"."last_login", "profiles_api_userprofile"."is_superuser", "profiles_api_userprofile"."email", "profiles_api_userprofile"."name", "profiles_api_userprofile"."lastname", "profiles_api_userprofile"."is_active", "profiles_api_userprofile"."is_staff", "profiles_api_userprofile"."country", "profiles_api_userprofile"."phone", "profiles_api_userprofile"."url_image", "profiles_api_userprofile"."state" FROM "profiles_api_userprofile" LIMIT 1000; args=()
Exception while resolving variable 'hide_label' in template 'rest_framework/horizontal/input.html'.
Traceback (most recent call last):
  File "/Library/WebServer/Documents/profiles-rest-api/profiles_api/lib/python3.6/site-packages/django/template/base.py", line 882, in _resolve_lookup
    current = current[bit]
KeyError: 'hide_label'

During handling of the above exception, another exception occurred:

Traceback (most recent call last):
  File "/Library/WebServer/Documents/profiles-rest-api/profiles_api/lib/python3.6/site-packages/django/template/base.py", line 890, in _resolve_lookup
    current = getattr(current, bit)
AttributeError: 'dict' object has no attribute 'hide_label'

During handling of the above exception, another exception occurred:

Traceback (most recent call last):
  File "/Library/WebServer/Documents/profiles-rest-api/profiles_api/lib/python3.6/site-packages/django/template/base.py", line 896, in _resolve_lookup
    current = current[int(bit)]
ValueError: invalid literal for int() with base 10: 'hide_label'

During handling of the above exception, another exception occurred:

Traceback (most recent call last):
  File "/Library/WebServer/Documents/profiles-rest-api/profiles_api/lib/python3.6/site-packages/django/template/base.py", line 903, in _resolve_lookup
    (bit, current))  # missing attribute
django.template.base.VariableDoesNotExist: Failed lookup for key [hide_label] in "{'base_template': 'input.html', 'input_type': 'text', 'template_pack': 'rest_framework/horizontal', 'renderer': <rest_framework.renderers.HTMLFormRenderer object at 0x1030d5e10>}"
Exception while resolving variable 'placeholder' in template 'rest_framework/horizontal/input.html'.
Traceback (most recent call last):
  File "/Library/WebServer/Documents/profiles-rest-api/profiles_api/lib/python3.6/site-packages/django/template/base.py", line 882, in _resolve_lookup
    current = current[bit]
KeyError: 'placeholder'

During handling of the above exception, another exception occurred:

Traceback (most recent call last):
  File "/Library/WebServer/Documents/profiles-rest-api/profiles_api/lib/python3.6/site-packages/django/template/base.py", line 890, in _resolve_lookup
    current = getattr(current, bit)
AttributeError: 'dict' object has no attribute 'placeholder'

During handling of the above exception, another exception occurred:

Traceback (most recent call last):
  File "/Library/WebServer/Documents/profiles-rest-api/profiles_api/lib/python3.6/site-packages/django/template/base.py", line 896, in _resolve_lookup
    current = current[int(bit)]
ValueError: invalid literal for int() with base 10: 'placeholder'

During handling of the above exception, another exception occurred:

Traceback (most recent call last):
  File "/Library/WebServer/Documents/profiles-rest-api/profiles_api/lib/python3.6/site-packages/django/template/base.py", line 903, in _resolve_lookup
    (bit, current))  # missing attribute
django.template.base.VariableDoesNotExist: Failed lookup for key [placeholder] in "{'base_template': 'input.html', 'input_type': 'text', 'template_pack': 'rest_framework/horizontal', 'renderer': <rest_framework.renderers.HTMLFormRenderer object at 0x1030d5e10>}"
Exception while resolving variable 'autofocus' in template 'rest_framework/horizontal/input.html'.
Traceback (most recent call last):
  File "/Library/WebServer/Documents/profiles-rest-api/profiles_api/lib/python3.6/site-packages/django/template/base.py", line 882, in _resolve_lookup
    current = current[bit]
KeyError: 'autofocus'

During handling of the above exception, another exception occurred:

Traceback (most recent call last):
  File "/Library/WebServer/Documents/profiles-rest-api/profiles_api/lib/python3.6/site-packages/django/template/base.py", line 890, in _resolve_lookup
    current = getattr(current, bit)
AttributeError: 'dict' object has no attribute 'autofocus'

During handling of the above exception, another exception occurred:

Traceback (most recent call last):
  File "/Library/WebServer/Documents/profiles-rest-api/profiles_api/lib/python3.6/site-packages/django/template/base.py", line 896, in _resolve_lookup
    current = current[int(bit)]
ValueError: invalid literal for int() with base 10: 'autofocus'

During handling of the above exception, another exception occurred:

Traceback (most recent call last):
  File "/Library/WebServer/Documents/profiles-rest-api/profiles_api/lib/python3.6/site-packages/django/template/base.py", line 903, in _resolve_lookup
    (bit, current))  # missing attribute
django.template.base.VariableDoesNotExist: Failed lookup for key [autofocus] in "{'base_template': 'input.html', 'input_type': 'text', 'template_pack': 'rest_framework/horizontal', 'renderer': <rest_framework.renderers.HTMLFormRenderer object at 0x1030d5e10>}"
Exception while resolving variable 'hide_label' in template 'rest_framework/horizontal/input.html'.
Traceback (most recent call last):
  File "/Library/WebServer/Documents/profiles-rest-api/profiles_api/lib/python3.6/site-packages/django/template/base.py", line 882, in _resolve_lookup
    current = current[bit]
KeyError: 'hide_label'

During handling of the above exception, another exception occurred:

Traceback (most recent call last):
  File "/Library/WebServer/Documents/profiles-rest-api/profiles_api/lib/python3.6/site-packages/django/template/base.py", line 890, in _resolve_lookup
    current = getattr(current, bit)
AttributeError: 'dict' object has no attribute 'hide_label'

During handling of the above exception, another exception occurred:

Traceback (most recent call last):
  File "/Library/WebServer/Documents/profiles-rest-api/profiles_api/lib/python3.6/site-packages/django/template/base.py", line 896, in _resolve_lookup
    current = current[int(bit)]
ValueError: invalid literal for int() with base 10: 'hide_label'

During handling of the above exception, another exception occurred:

Traceback (most recent call last):
  File "/Library/WebServer/Documents/profiles-rest-api/profiles_api/lib/python3.6/site-packages/django/template/base.py", line 903, in _resolve_lookup
    (bit, current))  # missing attribute
django.template.base.VariableDoesNotExist: Failed lookup for key [hide_label] in "{'base_template': 'input.html', 'input_type': 'text', 'template_pack': 'rest_framework/horizontal', 'renderer': <rest_framework.renderers.HTMLFormRenderer object at 0x1030d5e10>}"
Exception while resolving variable 'placeholder' in template 'rest_framework/horizontal/input.html'.
Traceback (most recent call last):
  File "/Library/WebServer/Documents/profiles-rest-api/profiles_api/lib/python3.6/site-packages/django/template/base.py", line 882, in _resolve_lookup
    current = current[bit]
KeyError: 'placeholder'

During handling of the above exception, another exception occurred:

Traceback (most recent call last):
  File "/Library/WebServer/Documents/profiles-rest-api/profiles_api/lib/python3.6/site-packages/django/template/base.py", line 890, in _resolve_lookup
    current = getattr(current, bit)
AttributeError: 'dict' object has no attribute 'placeholder'

During handling of the above exception, another exception occurred:

Traceback (most recent call last):
  File "/Library/WebServer/Documents/profiles-rest-api/profiles_api/lib/python3.6/site-packages/django/template/base.py", line 896, in _resolve_lookup
    current = current[int(bit)]
ValueError: invalid literal for int() with base 10: 'placeholder'

During handling of the above exception, another exception occurred:

Traceback (most recent call last):
  File "/Library/WebServer/Documents/profiles-rest-api/profiles_api/lib/python3.6/site-packages/django/template/base.py", line 903, in _resolve_lookup
    (bit, current))  # missing attribute
django.template.base.VariableDoesNotExist: Failed lookup for key [placeholder] in "{'base_template': 'input.html', 'input_type': 'text', 'template_pack': 'rest_framework/horizontal', 'renderer': <rest_framework.renderers.HTMLFormRenderer object at 0x1030d5e10>}"
Exception while resolving variable 'autofocus' in template 'rest_framework/horizontal/input.html'.
Traceback (most recent call last):
  File "/Library/WebServer/Documents/profiles-rest-api/profiles_api/lib/python3.6/site-packages/django/template/base.py", line 882, in _resolve_lookup
    current = current[bit]
KeyError: 'autofocus'

During handling of the above exception, another exception occurred:

Traceback (most recent call last):
  File "/Library/WebServer/Documents/profiles-rest-api/profiles_api/lib/python3.6/site-packages/django/template/base.py", line 890, in _resolve_lookup
    current = getattr(current, bit)
AttributeError: 'dict' object has no attribute 'autofocus'

During handling of the above exception, another exception occurred:

Traceback (most recent call last):
  File "/Library/WebServer/Documents/profiles-rest-api/profiles_api/lib/python3.6/site-packages/django/template/base.py", line 896, in _resolve_lookup
    current = current[int(bit)]
ValueError: invalid literal for int() with base 10: 'autofocus'

During handling of the above exception, another exception occurred:

Traceback (most recent call last):
  File "/Library/WebServer/Documents/profiles-rest-api/profiles_api/lib/python3.6/site-packages/django/template/base.py", line 903, in _resolve_lookup
    (bit, current))  # missing attribute
django.template.base.VariableDoesNotExist: Failed lookup for key [autofocus] in "{'base_template': 'input.html', 'input_type': 'text', 'template_pack': 'rest_framework/horizontal', 'renderer': <rest_framework.renderers.HTMLFormRenderer object at 0x1030d5e10>}"
Exception while resolving variable 'hide_label' in template 'rest_framework/horizontal/input.html'.
Traceback (most recent call last):
  File "/Library/WebServer/Documents/profiles-rest-api/profiles_api/lib/python3.6/site-packages/django/template/base.py", line 882, in _resolve_lookup
    current = current[bit]
KeyError: 'hide_label'

During handling of the above exception, another exception occurred:

Traceback (most recent call last):
  File "/Library/WebServer/Documents/profiles-rest-api/profiles_api/lib/python3.6/site-packages/django/template/base.py", line 890, in _resolve_lookup
    current = getattr(current, bit)
AttributeError: 'dict' object has no attribute 'hide_label'

During handling of the above exception, another exception occurred:

Traceback (most recent call last):
  File "/Library/WebServer/Documents/profiles-rest-api/profiles_api/lib/python3.6/site-packages/django/template/base.py", line 896, in _resolve_lookup
    current = current[int(bit)]
ValueError: invalid literal for int() with base 10: 'hide_label'

During handling of the above exception, another exception occurred:

Traceback (most recent call last):
  File "/Library/WebServer/Documents/profiles-rest-api/profiles_api/lib/python3.6/site-packages/django/template/base.py", line 903, in _resolve_lookup
    (bit, current))  # missing attribute
django.template.base.VariableDoesNotExist: Failed lookup for key [hide_label] in "{'base_template': 'input.html', 'input_type': 'number', 'template_pack': 'rest_framework/horizontal', 'renderer': <rest_framework.renderers.HTMLFormRenderer object at 0x1030d5e10>}"
Exception while resolving variable 'placeholder' in template 'rest_framework/horizontal/input.html'.
Traceback (most recent call last):
  File "/Library/WebServer/Documents/profiles-rest-api/profiles_api/lib/python3.6/site-packages/django/template/base.py", line 882, in _resolve_lookup
    current = current[bit]
KeyError: 'placeholder'

During handling of the above exception, another exception occurred:

Traceback (most recent call last):
  File "/Library/WebServer/Documents/profiles-rest-api/profiles_api/lib/python3.6/site-packages/django/template/base.py", line 890, in _resolve_lookup
    current = getattr(current, bit)
AttributeError: 'dict' object has no attribute 'placeholder'

During handling of the above exception, another exception occurred:

Traceback (most recent call last):
  File "/Library/WebServer/Documents/profiles-rest-api/profiles_api/lib/python3.6/site-packages/django/template/base.py", line 896, in _resolve_lookup
    current = current[int(bit)]
ValueError: invalid literal for int() with base 10: 'placeholder'

During handling of the above exception, another exception occurred:

Traceback (most recent call last):
  File "/Library/WebServer/Documents/profiles-rest-api/profiles_api/lib/python3.6/site-packages/django/template/base.py", line 903, in _resolve_lookup
    (bit, current))  # missing attribute
django.template.base.VariableDoesNotExist: Failed lookup for key [placeholder] in "{'base_template': 'input.html', 'input_type': 'number', 'template_pack': 'rest_framework/horizontal', 'renderer': <rest_framework.renderers.HTMLFormRenderer object at 0x1030d5e10>}"
Exception while resolving variable 'autofocus' in template 'rest_framework/horizontal/input.html'.
Traceback (most recent call last):
  File "/Library/WebServer/Documents/profiles-rest-api/profiles_api/lib/python3.6/site-packages/django/template/base.py", line 882, in _resolve_lookup
    current = current[bit]
KeyError: 'autofocus'

During handling of the above exception, another exception occurred:

Traceback (most recent call last):
  File "/Library/WebServer/Documents/profiles-rest-api/profiles_api/lib/python3.6/site-packages/django/template/base.py", line 890, in _resolve_lookup
    current = getattr(current, bit)
AttributeError: 'dict' object has no attribute 'autofocus'

During handling of the above exception, another exception occurred:

Traceback (most recent call last):
  File "/Library/WebServer/Documents/profiles-rest-api/profiles_api/lib/python3.6/site-packages/django/template/base.py", line 896, in _resolve_lookup
    current = current[int(bit)]
ValueError: invalid literal for int() with base 10: 'autofocus'

During handling of the above exception, another exception occurred:

Traceback (most recent call last):
  File "/Library/WebServer/Documents/profiles-rest-api/profiles_api/lib/python3.6/site-packages/django/template/base.py", line 903, in _resolve_lookup
    (bit, current))  # missing attribute
django.template.base.VariableDoesNotExist: Failed lookup for key [autofocus] in "{'base_template': 'input.html', 'input_type': 'number', 'template_pack': 'rest_framework/horizontal', 'renderer': <rest_framework.renderers.HTMLFormRenderer object at 0x1030d5e10>}"
"GET /api/user-process-history/ HTTP/1.1" 200 9985
(0.004) 
            SELECT c.relname, c.relkind
            FROM pg_catalog.pg_class c
            LEFT JOIN pg_catalog.pg_namespace n ON n.oid = c.relnamespace
            WHERE c.relkind IN ('r', 'v')
                AND n.nspname NOT IN ('pg_catalog', 'pg_toast')
                AND pg_catalog.pg_table_is_visible(c.oid); args=None
(0.001) SELECT "django_migrations"."app", "django_migrations"."name" FROM "django_migrations"; args=()
(0.002) SELECT "authtoken_token"."key", "authtoken_token"."user_id", "authtoken_token"."created", "profiles_api_userprofile"."id", "profiles_api_userprofile"."password", "profiles_api_userprofile"."last_login", "profiles_api_userprofile"."is_superuser", "profiles_api_userprofile"."email", "profiles_api_userprofile"."name", "profiles_api_userprofile"."lastname", "profiles_api_userprofile"."is_active", "profiles_api_userprofile"."is_staff", "profiles_api_userprofile"."country", "profiles_api_userprofile"."phone", "profiles_api_userprofile"."url_image", "profiles_api_userprofile"."state" FROM "authtoken_token" INNER JOIN "profiles_api_userprofile" ON ("authtoken_token"."user_id" = "profiles_api_userprofile"."id") WHERE "authtoken_token"."key" = '6412fe01d4f83677bafe2261d6dad0cc7405562b'; args=('6412fe01d4f83677bafe2261d6dad0cc7405562b',)
(0.001) SELECT "profiles_api_userprocesshistory"."id", "profiles_api_userprocesshistory"."user_profile_id", "profiles_api_userprocesshistory"."description", "profiles_api_userprocesshistory"."last_mod", "profiles_api_userprocesshistory"."remaining_storage", "profiles_api_userprocesshistory"."status" FROM "profiles_api_userprocesshistory" WHERE "profiles_api_userprocesshistory"."user_profile_id" = 5; args=(5,)
Exception while resolving variable 'hide_label' in template 'rest_framework/horizontal/select.html'.
Traceback (most recent call last):
  File "/Library/WebServer/Documents/profiles-rest-api/profiles_api/lib/python3.6/site-packages/django/template/base.py", line 882, in _resolve_lookup
    current = current[bit]
KeyError: 'hide_label'

During handling of the above exception, another exception occurred:

Traceback (most recent call last):
  File "/Library/WebServer/Documents/profiles-rest-api/profiles_api/lib/python3.6/site-packages/django/template/base.py", line 890, in _resolve_lookup
    current = getattr(current, bit)
AttributeError: 'dict' object has no attribute 'hide_label'

During handling of the above exception, another exception occurred:

Traceback (most recent call last):
  File "/Library/WebServer/Documents/profiles-rest-api/profiles_api/lib/python3.6/site-packages/django/template/base.py", line 896, in _resolve_lookup
    current = current[int(bit)]
ValueError: invalid literal for int() with base 10: 'hide_label'

During handling of the above exception, another exception occurred:

Traceback (most recent call last):
  File "/Library/WebServer/Documents/profiles-rest-api/profiles_api/lib/python3.6/site-packages/django/template/base.py", line 903, in _resolve_lookup
    (bit, current))  # missing attribute
django.template.base.VariableDoesNotExist: Failed lookup for key [hide_label] in "{'base_template': 'select.html', 'template_pack': 'rest_framework/horizontal', 'renderer': <rest_framework.renderers.HTMLFormRenderer object at 0x110134278>}"
Exception while resolving variable 'allow_blank' in template 'rest_framework/horizontal/select.html'.
Traceback (most recent call last):
  File "/Library/WebServer/Documents/profiles-rest-api/profiles_api/lib/python3.6/site-packages/django/template/base.py", line 882, in _resolve_lookup
    current = current[bit]
TypeError: 'BoundField' object is not subscriptable

During handling of the above exception, another exception occurred:

Traceback (most recent call last):
  File "/Library/WebServer/Documents/profiles-rest-api/profiles_api/lib/python3.6/site-packages/django/template/base.py", line 890, in _resolve_lookup
    current = getattr(current, bit)
  File "/Library/WebServer/Documents/profiles-rest-api/profiles_api/lib/python3.6/site-packages/rest_framework/utils/serializer_helpers.py", line 69, in __getattr__
    return getattr(self._field, attr_name)
AttributeError: 'PrimaryKeyRelatedField' object has no attribute 'allow_blank'

During handling of the above exception, another exception occurred:

Traceback (most recent call last):
  File "/Library/WebServer/Documents/profiles-rest-api/profiles_api/lib/python3.6/site-packages/django/template/base.py", line 896, in _resolve_lookup
    current = current[int(bit)]
ValueError: invalid literal for int() with base 10: 'allow_blank'

During handling of the above exception, another exception occurred:

Traceback (most recent call last):
  File "/Library/WebServer/Documents/profiles-rest-api/profiles_api/lib/python3.6/site-packages/django/template/base.py", line 903, in _resolve_lookup
    (bit, current))  # missing attribute
django.template.base.VariableDoesNotExist: Failed lookup for key [allow_blank] in '<BoundField value= errors=None>'
(0.000) SELECT "profiles_api_userprofile"."id", "profiles_api_userprofile"."password", "profiles_api_userprofile"."last_login", "profiles_api_userprofile"."is_superuser", "profiles_api_userprofile"."email", "profiles_api_userprofile"."name", "profiles_api_userprofile"."lastname", "profiles_api_userprofile"."is_active", "profiles_api_userprofile"."is_staff", "profiles_api_userprofile"."country", "profiles_api_userprofile"."phone", "profiles_api_userprofile"."url_image", "profiles_api_userprofile"."state" FROM "profiles_api_userprofile" LIMIT 1000; args=()
Exception while resolving variable 'hide_label' in template 'rest_framework/horizontal/input.html'.
Traceback (most recent call last):
  File "/Library/WebServer/Documents/profiles-rest-api/profiles_api/lib/python3.6/site-packages/django/template/base.py", line 882, in _resolve_lookup
    current = current[bit]
KeyError: 'hide_label'

During handling of the above exception, another exception occurred:

Traceback (most recent call last):
  File "/Library/WebServer/Documents/profiles-rest-api/profiles_api/lib/python3.6/site-packages/django/template/base.py", line 890, in _resolve_lookup
    current = getattr(current, bit)
AttributeError: 'dict' object has no attribute 'hide_label'

During handling of the above exception, another exception occurred:

Traceback (most recent call last):
  File "/Library/WebServer/Documents/profiles-rest-api/profiles_api/lib/python3.6/site-packages/django/template/base.py", line 896, in _resolve_lookup
    current = current[int(bit)]
ValueError: invalid literal for int() with base 10: 'hide_label'

During handling of the above exception, another exception occurred:

Traceback (most recent call last):
  File "/Library/WebServer/Documents/profiles-rest-api/profiles_api/lib/python3.6/site-packages/django/template/base.py", line 903, in _resolve_lookup
    (bit, current))  # missing attribute
django.template.base.VariableDoesNotExist: Failed lookup for key [hide_label] in "{'base_template': 'input.html', 'input_type': 'text', 'template_pack': 'rest_framework/horizontal', 'renderer': <rest_framework.renderers.HTMLFormRenderer object at 0x110134278>}"
Exception while resolving variable 'placeholder' in template 'rest_framework/horizontal/input.html'.
Traceback (most recent call last):
  File "/Library/WebServer/Documents/profiles-rest-api/profiles_api/lib/python3.6/site-packages/django/template/base.py", line 882, in _resolve_lookup
    current = current[bit]
KeyError: 'placeholder'

During handling of the above exception, another exception occurred:

Traceback (most recent call last):
  File "/Library/WebServer/Documents/profiles-rest-api/profiles_api/lib/python3.6/site-packages/django/template/base.py", line 890, in _resolve_lookup
    current = getattr(current, bit)
AttributeError: 'dict' object has no attribute 'placeholder'

During handling of the above exception, another exception occurred:

Traceback (most recent call last):
  File "/Library/WebServer/Documents/profiles-rest-api/profiles_api/lib/python3.6/site-packages/django/template/base.py", line 896, in _resolve_lookup
    current = current[int(bit)]
ValueError: invalid literal for int() with base 10: 'placeholder'

During handling of the above exception, another exception occurred:

Traceback (most recent call last):
  File "/Library/WebServer/Documents/profiles-rest-api/profiles_api/lib/python3.6/site-packages/django/template/base.py", line 903, in _resolve_lookup
    (bit, current))  # missing attribute
django.template.base.VariableDoesNotExist: Failed lookup for key [placeholder] in "{'base_template': 'input.html', 'input_type': 'text', 'template_pack': 'rest_framework/horizontal', 'renderer': <rest_framework.renderers.HTMLFormRenderer object at 0x110134278>}"
Exception while resolving variable 'autofocus' in template 'rest_framework/horizontal/input.html'.
Traceback (most recent call last):
  File "/Library/WebServer/Documents/profiles-rest-api/profiles_api/lib/python3.6/site-packages/django/template/base.py", line 882, in _resolve_lookup
    current = current[bit]
KeyError: 'autofocus'

During handling of the above exception, another exception occurred:

Traceback (most recent call last):
  File "/Library/WebServer/Documents/profiles-rest-api/profiles_api/lib/python3.6/site-packages/django/template/base.py", line 890, in _resolve_lookup
    current = getattr(current, bit)
AttributeError: 'dict' object has no attribute 'autofocus'

During handling of the above exception, another exception occurred:

Traceback (most recent call last):
  File "/Library/WebServer/Documents/profiles-rest-api/profiles_api/lib/python3.6/site-packages/django/template/base.py", line 896, in _resolve_lookup
    current = current[int(bit)]
ValueError: invalid literal for int() with base 10: 'autofocus'

During handling of the above exception, another exception occurred:

Traceback (most recent call last):
  File "/Library/WebServer/Documents/profiles-rest-api/profiles_api/lib/python3.6/site-packages/django/template/base.py", line 903, in _resolve_lookup
    (bit, current))  # missing attribute
django.template.base.VariableDoesNotExist: Failed lookup for key [autofocus] in "{'base_template': 'input.html', 'input_type': 'text', 'template_pack': 'rest_framework/horizontal', 'renderer': <rest_framework.renderers.HTMLFormRenderer object at 0x110134278>}"
Exception while resolving variable 'hide_label' in template 'rest_framework/horizontal/input.html'.
Traceback (most recent call last):
  File "/Library/WebServer/Documents/profiles-rest-api/profiles_api/lib/python3.6/site-packages/django/template/base.py", line 882, in _resolve_lookup
    current = current[bit]
KeyError: 'hide_label'

During handling of the above exception, another exception occurred:

Traceback (most recent call last):
  File "/Library/WebServer/Documents/profiles-rest-api/profiles_api/lib/python3.6/site-packages/django/template/base.py", line 890, in _resolve_lookup
    current = getattr(current, bit)
AttributeError: 'dict' object has no attribute 'hide_label'

During handling of the above exception, another exception occurred:

Traceback (most recent call last):
  File "/Library/WebServer/Documents/profiles-rest-api/profiles_api/lib/python3.6/site-packages/django/template/base.py", line 896, in _resolve_lookup
    current = current[int(bit)]
ValueError: invalid literal for int() with base 10: 'hide_label'

During handling of the above exception, another exception occurred:

Traceback (most recent call last):
  File "/Library/WebServer/Documents/profiles-rest-api/profiles_api/lib/python3.6/site-packages/django/template/base.py", line 903, in _resolve_lookup
    (bit, current))  # missing attribute
django.template.base.VariableDoesNotExist: Failed lookup for key [hide_label] in "{'base_template': 'input.html', 'input_type': 'text', 'template_pack': 'rest_framework/horizontal', 'renderer': <rest_framework.renderers.HTMLFormRenderer object at 0x110134278>}"
Exception while resolving variable 'placeholder' in template 'rest_framework/horizontal/input.html'.
Traceback (most recent call last):
  File "/Library/WebServer/Documents/profiles-rest-api/profiles_api/lib/python3.6/site-packages/django/template/base.py", line 882, in _resolve_lookup
    current = current[bit]
KeyError: 'placeholder'

During handling of the above exception, another exception occurred:

Traceback (most recent call last):
  File "/Library/WebServer/Documents/profiles-rest-api/profiles_api/lib/python3.6/site-packages/django/template/base.py", line 890, in _resolve_lookup
    current = getattr(current, bit)
AttributeError: 'dict' object has no attribute 'placeholder'

During handling of the above exception, another exception occurred:

Traceback (most recent call last):
  File "/Library/WebServer/Documents/profiles-rest-api/profiles_api/lib/python3.6/site-packages/django/template/base.py", line 896, in _resolve_lookup
    current = current[int(bit)]
ValueError: invalid literal for int() with base 10: 'placeholder'

During handling of the above exception, another exception occurred:

Traceback (most recent call last):
  File "/Library/WebServer/Documents/profiles-rest-api/profiles_api/lib/python3.6/site-packages/django/template/base.py", line 903, in _resolve_lookup
    (bit, current))  # missing attribute
django.template.base.VariableDoesNotExist: Failed lookup for key [placeholder] in "{'base_template': 'input.html', 'input_type': 'text', 'template_pack': 'rest_framework/horizontal', 'renderer': <rest_framework.renderers.HTMLFormRenderer object at 0x110134278>}"
Exception while resolving variable 'autofocus' in template 'rest_framework/horizontal/input.html'.
Traceback (most recent call last):
  File "/Library/WebServer/Documents/profiles-rest-api/profiles_api/lib/python3.6/site-packages/django/template/base.py", line 882, in _resolve_lookup
    current = current[bit]
KeyError: 'autofocus'

During handling of the above exception, another exception occurred:

Traceback (most recent call last):
  File "/Library/WebServer/Documents/profiles-rest-api/profiles_api/lib/python3.6/site-packages/django/template/base.py", line 890, in _resolve_lookup
    current = getattr(current, bit)
AttributeError: 'dict' object has no attribute 'autofocus'

During handling of the above exception, another exception occurred:

Traceback (most recent call last):
  File "/Library/WebServer/Documents/profiles-rest-api/profiles_api/lib/python3.6/site-packages/django/template/base.py", line 896, in _resolve_lookup
    current = current[int(bit)]
ValueError: invalid literal for int() with base 10: 'autofocus'

During handling of the above exception, another exception occurred:

Traceback (most recent call last):
  File "/Library/WebServer/Documents/profiles-rest-api/profiles_api/lib/python3.6/site-packages/django/template/base.py", line 903, in _resolve_lookup
    (bit, current))  # missing attribute
django.template.base.VariableDoesNotExist: Failed lookup for key [autofocus] in "{'base_template': 'input.html', 'input_type': 'text', 'template_pack': 'rest_framework/horizontal', 'renderer': <rest_framework.renderers.HTMLFormRenderer object at 0x110134278>}"
Exception while resolving variable 'hide_label' in template 'rest_framework/horizontal/input.html'.
Traceback (most recent call last):
  File "/Library/WebServer/Documents/profiles-rest-api/profiles_api/lib/python3.6/site-packages/django/template/base.py", line 882, in _resolve_lookup
    current = current[bit]
KeyError: 'hide_label'

During handling of the above exception, another exception occurred:

Traceback (most recent call last):
  File "/Library/WebServer/Documents/profiles-rest-api/profiles_api/lib/python3.6/site-packages/django/template/base.py", line 890, in _resolve_lookup
    current = getattr(current, bit)
AttributeError: 'dict' object has no attribute 'hide_label'

During handling of the above exception, another exception occurred:

Traceback (most recent call last):
  File "/Library/WebServer/Documents/profiles-rest-api/profiles_api/lib/python3.6/site-packages/django/template/base.py", line 896, in _resolve_lookup
    current = current[int(bit)]
ValueError: invalid literal for int() with base 10: 'hide_label'

During handling of the above exception, another exception occurred:

Traceback (most recent call last):
  File "/Library/WebServer/Documents/profiles-rest-api/profiles_api/lib/python3.6/site-packages/django/template/base.py", line 903, in _resolve_lookup
    (bit, current))  # missing attribute
django.template.base.VariableDoesNotExist: Failed lookup for key [hide_label] in "{'base_template': 'input.html', 'input_type': 'number', 'template_pack': 'rest_framework/horizontal', 'renderer': <rest_framework.renderers.HTMLFormRenderer object at 0x110134278>}"
Exception while resolving variable 'placeholder' in template 'rest_framework/horizontal/input.html'.
Traceback (most recent call last):
  File "/Library/WebServer/Documents/profiles-rest-api/profiles_api/lib/python3.6/site-packages/django/template/base.py", line 882, in _resolve_lookup
    current = current[bit]
KeyError: 'placeholder'

During handling of the above exception, another exception occurred:

Traceback (most recent call last):
  File "/Library/WebServer/Documents/profiles-rest-api/profiles_api/lib/python3.6/site-packages/django/template/base.py", line 890, in _resolve_lookup
    current = getattr(current, bit)
AttributeError: 'dict' object has no attribute 'placeholder'

During handling of the above exception, another exception occurred:

Traceback (most recent call last):
  File "/Library/WebServer/Documents/profiles-rest-api/profiles_api/lib/python3.6/site-packages/django/template/base.py", line 896, in _resolve_lookup
    current = current[int(bit)]
ValueError: invalid literal for int() with base 10: 'placeholder'

During handling of the above exception, another exception occurred:

Traceback (most recent call last):
  File "/Library/WebServer/Documents/profiles-rest-api/profiles_api/lib/python3.6/site-packages/django/template/base.py", line 903, in _resolve_lookup
    (bit, current))  # missing attribute
django.template.base.VariableDoesNotExist: Failed lookup for key [placeholder] in "{'base_template': 'input.html', 'input_type': 'number', 'template_pack': 'rest_framework/horizontal', 'renderer': <rest_framework.renderers.HTMLFormRenderer object at 0x110134278>}"
Exception while resolving variable 'autofocus' in template 'rest_framework/horizontal/input.html'.
Traceback (most recent call last):
  File "/Library/WebServer/Documents/profiles-rest-api/profiles_api/lib/python3.6/site-packages/django/template/base.py", line 882, in _resolve_lookup
    current = current[bit]
KeyError: 'autofocus'

During handling of the above exception, another exception occurred:

Traceback (most recent call last):
  File "/Library/WebServer/Documents/profiles-rest-api/profiles_api/lib/python3.6/site-packages/django/template/base.py", line 890, in _resolve_lookup
    current = getattr(current, bit)
AttributeError: 'dict' object has no attribute 'autofocus'

During handling of the above exception, another exception occurred:

Traceback (most recent call last):
  File "/Library/WebServer/Documents/profiles-rest-api/profiles_api/lib/python3.6/site-packages/django/template/base.py", line 896, in _resolve_lookup
    current = current[int(bit)]
ValueError: invalid literal for int() with base 10: 'autofocus'

During handling of the above exception, another exception occurred:

Traceback (most recent call last):
  File "/Library/WebServer/Documents/profiles-rest-api/profiles_api/lib/python3.6/site-packages/django/template/base.py", line 903, in _resolve_lookup
    (bit, current))  # missing attribute
django.template.base.VariableDoesNotExist: Failed lookup for key [autofocus] in "{'base_template': 'input.html', 'input_type': 'number', 'template_pack': 'rest_framework/horizontal', 'renderer': <rest_framework.renderers.HTMLFormRenderer object at 0x110134278>}"
"GET /api/user-process-history/ HTTP/1.1" 200 9985
(0.003) 
            SELECT c.relname, c.relkind
            FROM pg_catalog.pg_class c
            LEFT JOIN pg_catalog.pg_namespace n ON n.oid = c.relnamespace
            WHERE c.relkind IN ('r', 'v')
                AND n.nspname NOT IN ('pg_catalog', 'pg_toast')
                AND pg_catalog.pg_table_is_visible(c.oid); args=None
(0.001) SELECT "django_migrations"."app", "django_migrations"."name" FROM "django_migrations"; args=()
(0.002) 
            SELECT c.relname, c.relkind
            FROM pg_catalog.pg_class c
            LEFT JOIN pg_catalog.pg_namespace n ON n.oid = c.relnamespace
            WHERE c.relkind IN ('r', 'v')
                AND n.nspname NOT IN ('pg_catalog', 'pg_toast')
                AND pg_catalog.pg_table_is_visible(c.oid); args=None
(0.001) SELECT "django_migrations"."app", "django_migrations"."name" FROM "django_migrations"; args=()
"GET /api/ HTTP/1.1" 200 5972
(0.002) SELECT "authtoken_token"."key", "authtoken_token"."user_id", "authtoken_token"."created", "profiles_api_userprofile"."id", "profiles_api_userprofile"."password", "profiles_api_userprofile"."last_login", "profiles_api_userprofile"."is_superuser", "profiles_api_userprofile"."email", "profiles_api_userprofile"."name", "profiles_api_userprofile"."lastname", "profiles_api_userprofile"."is_active", "profiles_api_userprofile"."is_staff", "profiles_api_userprofile"."country", "profiles_api_userprofile"."phone", "profiles_api_userprofile"."url_image", "profiles_api_userprofile"."state" FROM "authtoken_token" INNER JOIN "profiles_api_userprofile" ON ("authtoken_token"."user_id" = "profiles_api_userprofile"."id") WHERE "authtoken_token"."key" = '6412fe01d4f83677bafe2261d6dad0cc7405562b'; args=('6412fe01d4f83677bafe2261d6dad0cc7405562b',)
(0.001) SELECT "profiles_api_userprocesshistory"."id", "profiles_api_userprocesshistory"."user_profile_id", "profiles_api_userprocesshistory"."description", "profiles_api_userprocesshistory"."last_mod", "profiles_api_userprocesshistory"."remaining_storage", "profiles_api_userprocesshistory"."status" FROM "profiles_api_userprocesshistory" WHERE "profiles_api_userprocesshistory"."user_profile_id" = 5; args=(5,)
Exception while resolving variable 'hide_label' in template 'rest_framework/horizontal/select.html'.
Traceback (most recent call last):
  File "/Library/WebServer/Documents/profiles-rest-api/profiles_api/lib/python3.6/site-packages/django/template/base.py", line 882, in _resolve_lookup
    current = current[bit]
KeyError: 'hide_label'

During handling of the above exception, another exception occurred:

Traceback (most recent call last):
  File "/Library/WebServer/Documents/profiles-rest-api/profiles_api/lib/python3.6/site-packages/django/template/base.py", line 890, in _resolve_lookup
    current = getattr(current, bit)
AttributeError: 'dict' object has no attribute 'hide_label'

During handling of the above exception, another exception occurred:

Traceback (most recent call last):
  File "/Library/WebServer/Documents/profiles-rest-api/profiles_api/lib/python3.6/site-packages/django/template/base.py", line 896, in _resolve_lookup
    current = current[int(bit)]
ValueError: invalid literal for int() with base 10: 'hide_label'

During handling of the above exception, another exception occurred:

Traceback (most recent call last):
  File "/Library/WebServer/Documents/profiles-rest-api/profiles_api/lib/python3.6/site-packages/django/template/base.py", line 903, in _resolve_lookup
    (bit, current))  # missing attribute
django.template.base.VariableDoesNotExist: Failed lookup for key [hide_label] in "{'base_template': 'select.html', 'template_pack': 'rest_framework/horizontal', 'renderer': <rest_framework.renderers.HTMLFormRenderer object at 0x104e9c470>}"
Exception while resolving variable 'allow_blank' in template 'rest_framework/horizontal/select.html'.
Traceback (most recent call last):
  File "/Library/WebServer/Documents/profiles-rest-api/profiles_api/lib/python3.6/site-packages/django/template/base.py", line 882, in _resolve_lookup
    current = current[bit]
TypeError: 'BoundField' object is not subscriptable

During handling of the above exception, another exception occurred:

Traceback (most recent call last):
  File "/Library/WebServer/Documents/profiles-rest-api/profiles_api/lib/python3.6/site-packages/django/template/base.py", line 890, in _resolve_lookup
    current = getattr(current, bit)
  File "/Library/WebServer/Documents/profiles-rest-api/profiles_api/lib/python3.6/site-packages/rest_framework/utils/serializer_helpers.py", line 69, in __getattr__
    return getattr(self._field, attr_name)
AttributeError: 'PrimaryKeyRelatedField' object has no attribute 'allow_blank'

During handling of the above exception, another exception occurred:

Traceback (most recent call last):
  File "/Library/WebServer/Documents/profiles-rest-api/profiles_api/lib/python3.6/site-packages/django/template/base.py", line 896, in _resolve_lookup
    current = current[int(bit)]
ValueError: invalid literal for int() with base 10: 'allow_blank'

During handling of the above exception, another exception occurred:

Traceback (most recent call last):
  File "/Library/WebServer/Documents/profiles-rest-api/profiles_api/lib/python3.6/site-packages/django/template/base.py", line 903, in _resolve_lookup
    (bit, current))  # missing attribute
django.template.base.VariableDoesNotExist: Failed lookup for key [allow_blank] in '<BoundField value= errors=None>'
(0.000) SELECT "profiles_api_userprofile"."id", "profiles_api_userprofile"."password", "profiles_api_userprofile"."last_login", "profiles_api_userprofile"."is_superuser", "profiles_api_userprofile"."email", "profiles_api_userprofile"."name", "profiles_api_userprofile"."lastname", "profiles_api_userprofile"."is_active", "profiles_api_userprofile"."is_staff", "profiles_api_userprofile"."country", "profiles_api_userprofile"."phone", "profiles_api_userprofile"."url_image", "profiles_api_userprofile"."state" FROM "profiles_api_userprofile" LIMIT 1000; args=()
Exception while resolving variable 'hide_label' in template 'rest_framework/horizontal/input.html'.
Traceback (most recent call last):
  File "/Library/WebServer/Documents/profiles-rest-api/profiles_api/lib/python3.6/site-packages/django/template/base.py", line 882, in _resolve_lookup
    current = current[bit]
KeyError: 'hide_label'

During handling of the above exception, another exception occurred:

Traceback (most recent call last):
  File "/Library/WebServer/Documents/profiles-rest-api/profiles_api/lib/python3.6/site-packages/django/template/base.py", line 890, in _resolve_lookup
    current = getattr(current, bit)
AttributeError: 'dict' object has no attribute 'hide_label'

During handling of the above exception, another exception occurred:

Traceback (most recent call last):
  File "/Library/WebServer/Documents/profiles-rest-api/profiles_api/lib/python3.6/site-packages/django/template/base.py", line 896, in _resolve_lookup
    current = current[int(bit)]
ValueError: invalid literal for int() with base 10: 'hide_label'

During handling of the above exception, another exception occurred:

Traceback (most recent call last):
  File "/Library/WebServer/Documents/profiles-rest-api/profiles_api/lib/python3.6/site-packages/django/template/base.py", line 903, in _resolve_lookup
    (bit, current))  # missing attribute
django.template.base.VariableDoesNotExist: Failed lookup for key [hide_label] in "{'base_template': 'input.html', 'input_type': 'text', 'template_pack': 'rest_framework/horizontal', 'renderer': <rest_framework.renderers.HTMLFormRenderer object at 0x104e9c470>}"
Exception while resolving variable 'placeholder' in template 'rest_framework/horizontal/input.html'.
Traceback (most recent call last):
  File "/Library/WebServer/Documents/profiles-rest-api/profiles_api/lib/python3.6/site-packages/django/template/base.py", line 882, in _resolve_lookup
    current = current[bit]
KeyError: 'placeholder'

During handling of the above exception, another exception occurred:

Traceback (most recent call last):
  File "/Library/WebServer/Documents/profiles-rest-api/profiles_api/lib/python3.6/site-packages/django/template/base.py", line 890, in _resolve_lookup
    current = getattr(current, bit)
AttributeError: 'dict' object has no attribute 'placeholder'

During handling of the above exception, another exception occurred:

Traceback (most recent call last):
  File "/Library/WebServer/Documents/profiles-rest-api/profiles_api/lib/python3.6/site-packages/django/template/base.py", line 896, in _resolve_lookup
    current = current[int(bit)]
ValueError: invalid literal for int() with base 10: 'placeholder'

During handling of the above exception, another exception occurred:

Traceback (most recent call last):
  File "/Library/WebServer/Documents/profiles-rest-api/profiles_api/lib/python3.6/site-packages/django/template/base.py", line 903, in _resolve_lookup
    (bit, current))  # missing attribute
django.template.base.VariableDoesNotExist: Failed lookup for key [placeholder] in "{'base_template': 'input.html', 'input_type': 'text', 'template_pack': 'rest_framework/horizontal', 'renderer': <rest_framework.renderers.HTMLFormRenderer object at 0x104e9c470>}"
Exception while resolving variable 'autofocus' in template 'rest_framework/horizontal/input.html'.
Traceback (most recent call last):
  File "/Library/WebServer/Documents/profiles-rest-api/profiles_api/lib/python3.6/site-packages/django/template/base.py", line 882, in _resolve_lookup
    current = current[bit]
KeyError: 'autofocus'

During handling of the above exception, another exception occurred:

Traceback (most recent call last):
  File "/Library/WebServer/Documents/profiles-rest-api/profiles_api/lib/python3.6/site-packages/django/template/base.py", line 890, in _resolve_lookup
    current = getattr(current, bit)
AttributeError: 'dict' object has no attribute 'autofocus'

During handling of the above exception, another exception occurred:

Traceback (most recent call last):
  File "/Library/WebServer/Documents/profiles-rest-api/profiles_api/lib/python3.6/site-packages/django/template/base.py", line 896, in _resolve_lookup
    current = current[int(bit)]
ValueError: invalid literal for int() with base 10: 'autofocus'

During handling of the above exception, another exception occurred:

Traceback (most recent call last):
  File "/Library/WebServer/Documents/profiles-rest-api/profiles_api/lib/python3.6/site-packages/django/template/base.py", line 903, in _resolve_lookup
    (bit, current))  # missing attribute
django.template.base.VariableDoesNotExist: Failed lookup for key [autofocus] in "{'base_template': 'input.html', 'input_type': 'text', 'template_pack': 'rest_framework/horizontal', 'renderer': <rest_framework.renderers.HTMLFormRenderer object at 0x104e9c470>}"
Exception while resolving variable 'hide_label' in template 'rest_framework/horizontal/input.html'.
Traceback (most recent call last):
  File "/Library/WebServer/Documents/profiles-rest-api/profiles_api/lib/python3.6/site-packages/django/template/base.py", line 882, in _resolve_lookup
    current = current[bit]
KeyError: 'hide_label'

During handling of the above exception, another exception occurred:

Traceback (most recent call last):
  File "/Library/WebServer/Documents/profiles-rest-api/profiles_api/lib/python3.6/site-packages/django/template/base.py", line 890, in _resolve_lookup
    current = getattr(current, bit)
AttributeError: 'dict' object has no attribute 'hide_label'

During handling of the above exception, another exception occurred:

Traceback (most recent call last):
  File "/Library/WebServer/Documents/profiles-rest-api/profiles_api/lib/python3.6/site-packages/django/template/base.py", line 896, in _resolve_lookup
    current = current[int(bit)]
ValueError: invalid literal for int() with base 10: 'hide_label'

During handling of the above exception, another exception occurred:

Traceback (most recent call last):
  File "/Library/WebServer/Documents/profiles-rest-api/profiles_api/lib/python3.6/site-packages/django/template/base.py", line 903, in _resolve_lookup
    (bit, current))  # missing attribute
django.template.base.VariableDoesNotExist: Failed lookup for key [hide_label] in "{'base_template': 'input.html', 'input_type': 'text', 'template_pack': 'rest_framework/horizontal', 'renderer': <rest_framework.renderers.HTMLFormRenderer object at 0x104e9c470>}"
Exception while resolving variable 'placeholder' in template 'rest_framework/horizontal/input.html'.
Traceback (most recent call last):
  File "/Library/WebServer/Documents/profiles-rest-api/profiles_api/lib/python3.6/site-packages/django/template/base.py", line 882, in _resolve_lookup
    current = current[bit]
KeyError: 'placeholder'

During handling of the above exception, another exception occurred:

Traceback (most recent call last):
  File "/Library/WebServer/Documents/profiles-rest-api/profiles_api/lib/python3.6/site-packages/django/template/base.py", line 890, in _resolve_lookup
    current = getattr(current, bit)
AttributeError: 'dict' object has no attribute 'placeholder'

During handling of the above exception, another exception occurred:

Traceback (most recent call last):
  File "/Library/WebServer/Documents/profiles-rest-api/profiles_api/lib/python3.6/site-packages/django/template/base.py", line 896, in _resolve_lookup
    current = current[int(bit)]
ValueError: invalid literal for int() with base 10: 'placeholder'

During handling of the above exception, another exception occurred:

Traceback (most recent call last):
  File "/Library/WebServer/Documents/profiles-rest-api/profiles_api/lib/python3.6/site-packages/django/template/base.py", line 903, in _resolve_lookup
    (bit, current))  # missing attribute
django.template.base.VariableDoesNotExist: Failed lookup for key [placeholder] in "{'base_template': 'input.html', 'input_type': 'text', 'template_pack': 'rest_framework/horizontal', 'renderer': <rest_framework.renderers.HTMLFormRenderer object at 0x104e9c470>}"
Exception while resolving variable 'autofocus' in template 'rest_framework/horizontal/input.html'.
Traceback (most recent call last):
  File "/Library/WebServer/Documents/profiles-rest-api/profiles_api/lib/python3.6/site-packages/django/template/base.py", line 882, in _resolve_lookup
    current = current[bit]
KeyError: 'autofocus'

During handling of the above exception, another exception occurred:

Traceback (most recent call last):
  File "/Library/WebServer/Documents/profiles-rest-api/profiles_api/lib/python3.6/site-packages/django/template/base.py", line 890, in _resolve_lookup
    current = getattr(current, bit)
AttributeError: 'dict' object has no attribute 'autofocus'

During handling of the above exception, another exception occurred:

Traceback (most recent call last):
  File "/Library/WebServer/Documents/profiles-rest-api/profiles_api/lib/python3.6/site-packages/django/template/base.py", line 896, in _resolve_lookup
    current = current[int(bit)]
ValueError: invalid literal for int() with base 10: 'autofocus'

During handling of the above exception, another exception occurred:

Traceback (most recent call last):
  File "/Library/WebServer/Documents/profiles-rest-api/profiles_api/lib/python3.6/site-packages/django/template/base.py", line 903, in _resolve_lookup
    (bit, current))  # missing attribute
django.template.base.VariableDoesNotExist: Failed lookup for key [autofocus] in "{'base_template': 'input.html', 'input_type': 'text', 'template_pack': 'rest_framework/horizontal', 'renderer': <rest_framework.renderers.HTMLFormRenderer object at 0x104e9c470>}"
Exception while resolving variable 'hide_label' in template 'rest_framework/horizontal/input.html'.
Traceback (most recent call last):
  File "/Library/WebServer/Documents/profiles-rest-api/profiles_api/lib/python3.6/site-packages/django/template/base.py", line 882, in _resolve_lookup
    current = current[bit]
KeyError: 'hide_label'

During handling of the above exception, another exception occurred:

Traceback (most recent call last):
  File "/Library/WebServer/Documents/profiles-rest-api/profiles_api/lib/python3.6/site-packages/django/template/base.py", line 890, in _resolve_lookup
    current = getattr(current, bit)
AttributeError: 'dict' object has no attribute 'hide_label'

During handling of the above exception, another exception occurred:

Traceback (most recent call last):
  File "/Library/WebServer/Documents/profiles-rest-api/profiles_api/lib/python3.6/site-packages/django/template/base.py", line 896, in _resolve_lookup
    current = current[int(bit)]
ValueError: invalid literal for int() with base 10: 'hide_label'

During handling of the above exception, another exception occurred:

Traceback (most recent call last):
  File "/Library/WebServer/Documents/profiles-rest-api/profiles_api/lib/python3.6/site-packages/django/template/base.py", line 903, in _resolve_lookup
    (bit, current))  # missing attribute
django.template.base.VariableDoesNotExist: Failed lookup for key [hide_label] in "{'base_template': 'input.html', 'input_type': 'number', 'template_pack': 'rest_framework/horizontal', 'renderer': <rest_framework.renderers.HTMLFormRenderer object at 0x104e9c470>}"
Exception while resolving variable 'placeholder' in template 'rest_framework/horizontal/input.html'.
Traceback (most recent call last):
  File "/Library/WebServer/Documents/profiles-rest-api/profiles_api/lib/python3.6/site-packages/django/template/base.py", line 882, in _resolve_lookup
    current = current[bit]
KeyError: 'placeholder'

During handling of the above exception, another exception occurred:

Traceback (most recent call last):
  File "/Library/WebServer/Documents/profiles-rest-api/profiles_api/lib/python3.6/site-packages/django/template/base.py", line 890, in _resolve_lookup
    current = getattr(current, bit)
AttributeError: 'dict' object has no attribute 'placeholder'

During handling of the above exception, another exception occurred:

Traceback (most recent call last):
  File "/Library/WebServer/Documents/profiles-rest-api/profiles_api/lib/python3.6/site-packages/django/template/base.py", line 896, in _resolve_lookup
    current = current[int(bit)]
ValueError: invalid literal for int() with base 10: 'placeholder'

During handling of the above exception, another exception occurred:

Traceback (most recent call last):
  File "/Library/WebServer/Documents/profiles-rest-api/profiles_api/lib/python3.6/site-packages/django/template/base.py", line 903, in _resolve_lookup
    (bit, current))  # missing attribute
django.template.base.VariableDoesNotExist: Failed lookup for key [placeholder] in "{'base_template': 'input.html', 'input_type': 'number', 'template_pack': 'rest_framework/horizontal', 'renderer': <rest_framework.renderers.HTMLFormRenderer object at 0x104e9c470>}"
Exception while resolving variable 'autofocus' in template 'rest_framework/horizontal/input.html'.
Traceback (most recent call last):
  File "/Library/WebServer/Documents/profiles-rest-api/profiles_api/lib/python3.6/site-packages/django/template/base.py", line 882, in _resolve_lookup
    current = current[bit]
KeyError: 'autofocus'

During handling of the above exception, another exception occurred:

Traceback (most recent call last):
  File "/Library/WebServer/Documents/profiles-rest-api/profiles_api/lib/python3.6/site-packages/django/template/base.py", line 890, in _resolve_lookup
    current = getattr(current, bit)
AttributeError: 'dict' object has no attribute 'autofocus'

During handling of the above exception, another exception occurred:

Traceback (most recent call last):
  File "/Library/WebServer/Documents/profiles-rest-api/profiles_api/lib/python3.6/site-packages/django/template/base.py", line 896, in _resolve_lookup
    current = current[int(bit)]
ValueError: invalid literal for int() with base 10: 'autofocus'

During handling of the above exception, another exception occurred:

Traceback (most recent call last):
  File "/Library/WebServer/Documents/profiles-rest-api/profiles_api/lib/python3.6/site-packages/django/template/base.py", line 903, in _resolve_lookup
    (bit, current))  # missing attribute
django.template.base.VariableDoesNotExist: Failed lookup for key [autofocus] in "{'base_template': 'input.html', 'input_type': 'number', 'template_pack': 'rest_framework/horizontal', 'renderer': <rest_framework.renderers.HTMLFormRenderer object at 0x104e9c470>}"
"GET /api/user-process-history/ HTTP/1.1" 200 9985
(0.002) 
            SELECT c.relname, c.relkind
            FROM pg_catalog.pg_class c
            LEFT JOIN pg_catalog.pg_namespace n ON n.oid = c.relnamespace
            WHERE c.relkind IN ('r', 'v')
                AND n.nspname NOT IN ('pg_catalog', 'pg_toast')
                AND pg_catalog.pg_table_is_visible(c.oid); args=None
(0.001) SELECT "django_migrations"."app", "django_migrations"."name" FROM "django_migrations"; args=()
(0.002) SELECT "authtoken_token"."key", "authtoken_token"."user_id", "authtoken_token"."created", "profiles_api_userprofile"."id", "profiles_api_userprofile"."password", "profiles_api_userprofile"."last_login", "profiles_api_userprofile"."is_superuser", "profiles_api_userprofile"."email", "profiles_api_userprofile"."name", "profiles_api_userprofile"."lastname", "profiles_api_userprofile"."is_active", "profiles_api_userprofile"."is_staff", "profiles_api_userprofile"."country", "profiles_api_userprofile"."phone", "profiles_api_userprofile"."url_image", "profiles_api_userprofile"."state" FROM "authtoken_token" INNER JOIN "profiles_api_userprofile" ON ("authtoken_token"."user_id" = "profiles_api_userprofile"."id") WHERE "authtoken_token"."key" = '6412fe01d4f83677bafe2261d6dad0cc7405562b'; args=('6412fe01d4f83677bafe2261d6dad0cc7405562b',)
(0.001) SELECT "profiles_api_userprocesshistory"."id", "profiles_api_userprocesshistory"."user_profile_id", "profiles_api_userprocesshistory"."description", "profiles_api_userprocesshistory"."last_mod", "profiles_api_userprocesshistory"."remaining_storage", "profiles_api_userprocesshistory"."status" FROM "profiles_api_userprocesshistory" WHERE "profiles_api_userprocesshistory"."user_profile_id" = 5; args=(5,)
Exception while resolving variable 'hide_label' in template 'rest_framework/horizontal/select.html'.
Traceback (most recent call last):
  File "/Library/WebServer/Documents/profiles-rest-api/profiles_api/lib/python3.6/site-packages/django/template/base.py", line 882, in _resolve_lookup
    current = current[bit]
KeyError: 'hide_label'

During handling of the above exception, another exception occurred:

Traceback (most recent call last):
  File "/Library/WebServer/Documents/profiles-rest-api/profiles_api/lib/python3.6/site-packages/django/template/base.py", line 890, in _resolve_lookup
    current = getattr(current, bit)
AttributeError: 'dict' object has no attribute 'hide_label'

During handling of the above exception, another exception occurred:

Traceback (most recent call last):
  File "/Library/WebServer/Documents/profiles-rest-api/profiles_api/lib/python3.6/site-packages/django/template/base.py", line 896, in _resolve_lookup
    current = current[int(bit)]
ValueError: invalid literal for int() with base 10: 'hide_label'

During handling of the above exception, another exception occurred:

Traceback (most recent call last):
  File "/Library/WebServer/Documents/profiles-rest-api/profiles_api/lib/python3.6/site-packages/django/template/base.py", line 903, in _resolve_lookup
    (bit, current))  # missing attribute
django.template.base.VariableDoesNotExist: Failed lookup for key [hide_label] in "{'base_template': 'select.html', 'template_pack': 'rest_framework/horizontal', 'renderer': <rest_framework.renderers.HTMLFormRenderer object at 0x1030d41d0>}"
Exception while resolving variable 'allow_blank' in template 'rest_framework/horizontal/select.html'.
Traceback (most recent call last):
  File "/Library/WebServer/Documents/profiles-rest-api/profiles_api/lib/python3.6/site-packages/django/template/base.py", line 882, in _resolve_lookup
    current = current[bit]
TypeError: 'BoundField' object is not subscriptable

During handling of the above exception, another exception occurred:

Traceback (most recent call last):
  File "/Library/WebServer/Documents/profiles-rest-api/profiles_api/lib/python3.6/site-packages/django/template/base.py", line 890, in _resolve_lookup
    current = getattr(current, bit)
  File "/Library/WebServer/Documents/profiles-rest-api/profiles_api/lib/python3.6/site-packages/rest_framework/utils/serializer_helpers.py", line 69, in __getattr__
    return getattr(self._field, attr_name)
AttributeError: 'PrimaryKeyRelatedField' object has no attribute 'allow_blank'

During handling of the above exception, another exception occurred:

Traceback (most recent call last):
  File "/Library/WebServer/Documents/profiles-rest-api/profiles_api/lib/python3.6/site-packages/django/template/base.py", line 896, in _resolve_lookup
    current = current[int(bit)]
ValueError: invalid literal for int() with base 10: 'allow_blank'

During handling of the above exception, another exception occurred:

Traceback (most recent call last):
  File "/Library/WebServer/Documents/profiles-rest-api/profiles_api/lib/python3.6/site-packages/django/template/base.py", line 903, in _resolve_lookup
    (bit, current))  # missing attribute
django.template.base.VariableDoesNotExist: Failed lookup for key [allow_blank] in '<BoundField value= errors=None>'
(0.001) SELECT "profiles_api_userprofile"."id", "profiles_api_userprofile"."password", "profiles_api_userprofile"."last_login", "profiles_api_userprofile"."is_superuser", "profiles_api_userprofile"."email", "profiles_api_userprofile"."name", "profiles_api_userprofile"."lastname", "profiles_api_userprofile"."is_active", "profiles_api_userprofile"."is_staff", "profiles_api_userprofile"."country", "profiles_api_userprofile"."phone", "profiles_api_userprofile"."url_image", "profiles_api_userprofile"."state" FROM "profiles_api_userprofile" LIMIT 1000; args=()
Exception while resolving variable 'hide_label' in template 'rest_framework/horizontal/input.html'.
Traceback (most recent call last):
  File "/Library/WebServer/Documents/profiles-rest-api/profiles_api/lib/python3.6/site-packages/django/template/base.py", line 882, in _resolve_lookup
    current = current[bit]
KeyError: 'hide_label'

During handling of the above exception, another exception occurred:

Traceback (most recent call last):
  File "/Library/WebServer/Documents/profiles-rest-api/profiles_api/lib/python3.6/site-packages/django/template/base.py", line 890, in _resolve_lookup
    current = getattr(current, bit)
AttributeError: 'dict' object has no attribute 'hide_label'

During handling of the above exception, another exception occurred:

Traceback (most recent call last):
  File "/Library/WebServer/Documents/profiles-rest-api/profiles_api/lib/python3.6/site-packages/django/template/base.py", line 896, in _resolve_lookup
    current = current[int(bit)]
ValueError: invalid literal for int() with base 10: 'hide_label'

During handling of the above exception, another exception occurred:

Traceback (most recent call last):
  File "/Library/WebServer/Documents/profiles-rest-api/profiles_api/lib/python3.6/site-packages/django/template/base.py", line 903, in _resolve_lookup
    (bit, current))  # missing attribute
django.template.base.VariableDoesNotExist: Failed lookup for key [hide_label] in "{'base_template': 'input.html', 'input_type': 'text', 'template_pack': 'rest_framework/horizontal', 'renderer': <rest_framework.renderers.HTMLFormRenderer object at 0x1030d41d0>}"
Exception while resolving variable 'placeholder' in template 'rest_framework/horizontal/input.html'.
Traceback (most recent call last):
  File "/Library/WebServer/Documents/profiles-rest-api/profiles_api/lib/python3.6/site-packages/django/template/base.py", line 882, in _resolve_lookup
    current = current[bit]
KeyError: 'placeholder'

During handling of the above exception, another exception occurred:

Traceback (most recent call last):
  File "/Library/WebServer/Documents/profiles-rest-api/profiles_api/lib/python3.6/site-packages/django/template/base.py", line 890, in _resolve_lookup
    current = getattr(current, bit)
AttributeError: 'dict' object has no attribute 'placeholder'

During handling of the above exception, another exception occurred:

Traceback (most recent call last):
  File "/Library/WebServer/Documents/profiles-rest-api/profiles_api/lib/python3.6/site-packages/django/template/base.py", line 896, in _resolve_lookup
    current = current[int(bit)]
ValueError: invalid literal for int() with base 10: 'placeholder'

During handling of the above exception, another exception occurred:

Traceback (most recent call last):
  File "/Library/WebServer/Documents/profiles-rest-api/profiles_api/lib/python3.6/site-packages/django/template/base.py", line 903, in _resolve_lookup
    (bit, current))  # missing attribute
django.template.base.VariableDoesNotExist: Failed lookup for key [placeholder] in "{'base_template': 'input.html', 'input_type': 'text', 'template_pack': 'rest_framework/horizontal', 'renderer': <rest_framework.renderers.HTMLFormRenderer object at 0x1030d41d0>}"
Exception while resolving variable 'autofocus' in template 'rest_framework/horizontal/input.html'.
Traceback (most recent call last):
  File "/Library/WebServer/Documents/profiles-rest-api/profiles_api/lib/python3.6/site-packages/django/template/base.py", line 882, in _resolve_lookup
    current = current[bit]
KeyError: 'autofocus'

During handling of the above exception, another exception occurred:

Traceback (most recent call last):
  File "/Library/WebServer/Documents/profiles-rest-api/profiles_api/lib/python3.6/site-packages/django/template/base.py", line 890, in _resolve_lookup
    current = getattr(current, bit)
AttributeError: 'dict' object has no attribute 'autofocus'

During handling of the above exception, another exception occurred:

Traceback (most recent call last):
  File "/Library/WebServer/Documents/profiles-rest-api/profiles_api/lib/python3.6/site-packages/django/template/base.py", line 896, in _resolve_lookup
    current = current[int(bit)]
ValueError: invalid literal for int() with base 10: 'autofocus'

During handling of the above exception, another exception occurred:

Traceback (most recent call last):
  File "/Library/WebServer/Documents/profiles-rest-api/profiles_api/lib/python3.6/site-packages/django/template/base.py", line 903, in _resolve_lookup
    (bit, current))  # missing attribute
django.template.base.VariableDoesNotExist: Failed lookup for key [autofocus] in "{'base_template': 'input.html', 'input_type': 'text', 'template_pack': 'rest_framework/horizontal', 'renderer': <rest_framework.renderers.HTMLFormRenderer object at 0x1030d41d0>}"
Exception while resolving variable 'hide_label' in template 'rest_framework/horizontal/input.html'.
Traceback (most recent call last):
  File "/Library/WebServer/Documents/profiles-rest-api/profiles_api/lib/python3.6/site-packages/django/template/base.py", line 882, in _resolve_lookup
    current = current[bit]
KeyError: 'hide_label'

During handling of the above exception, another exception occurred:

Traceback (most recent call last):
  File "/Library/WebServer/Documents/profiles-rest-api/profiles_api/lib/python3.6/site-packages/django/template/base.py", line 890, in _resolve_lookup
    current = getattr(current, bit)
AttributeError: 'dict' object has no attribute 'hide_label'

During handling of the above exception, another exception occurred:

Traceback (most recent call last):
  File "/Library/WebServer/Documents/profiles-rest-api/profiles_api/lib/python3.6/site-packages/django/template/base.py", line 896, in _resolve_lookup
    current = current[int(bit)]
ValueError: invalid literal for int() with base 10: 'hide_label'

During handling of the above exception, another exception occurred:

Traceback (most recent call last):
  File "/Library/WebServer/Documents/profiles-rest-api/profiles_api/lib/python3.6/site-packages/django/template/base.py", line 903, in _resolve_lookup
    (bit, current))  # missing attribute
django.template.base.VariableDoesNotExist: Failed lookup for key [hide_label] in "{'base_template': 'input.html', 'input_type': 'text', 'template_pack': 'rest_framework/horizontal', 'renderer': <rest_framework.renderers.HTMLFormRenderer object at 0x1030d41d0>}"
Exception while resolving variable 'placeholder' in template 'rest_framework/horizontal/input.html'.
Traceback (most recent call last):
  File "/Library/WebServer/Documents/profiles-rest-api/profiles_api/lib/python3.6/site-packages/django/template/base.py", line 882, in _resolve_lookup
    current = current[bit]
KeyError: 'placeholder'

During handling of the above exception, another exception occurred:

Traceback (most recent call last):
  File "/Library/WebServer/Documents/profiles-rest-api/profiles_api/lib/python3.6/site-packages/django/template/base.py", line 890, in _resolve_lookup
    current = getattr(current, bit)
AttributeError: 'dict' object has no attribute 'placeholder'

During handling of the above exception, another exception occurred:

Traceback (most recent call last):
  File "/Library/WebServer/Documents/profiles-rest-api/profiles_api/lib/python3.6/site-packages/django/template/base.py", line 896, in _resolve_lookup
    current = current[int(bit)]
ValueError: invalid literal for int() with base 10: 'placeholder'

During handling of the above exception, another exception occurred:

Traceback (most recent call last):
  File "/Library/WebServer/Documents/profiles-rest-api/profiles_api/lib/python3.6/site-packages/django/template/base.py", line 903, in _resolve_lookup
    (bit, current))  # missing attribute
django.template.base.VariableDoesNotExist: Failed lookup for key [placeholder] in "{'base_template': 'input.html', 'input_type': 'text', 'template_pack': 'rest_framework/horizontal', 'renderer': <rest_framework.renderers.HTMLFormRenderer object at 0x1030d41d0>}"
Exception while resolving variable 'autofocus' in template 'rest_framework/horizontal/input.html'.
Traceback (most recent call last):
  File "/Library/WebServer/Documents/profiles-rest-api/profiles_api/lib/python3.6/site-packages/django/template/base.py", line 882, in _resolve_lookup
    current = current[bit]
KeyError: 'autofocus'

During handling of the above exception, another exception occurred:

Traceback (most recent call last):
  File "/Library/WebServer/Documents/profiles-rest-api/profiles_api/lib/python3.6/site-packages/django/template/base.py", line 890, in _resolve_lookup
    current = getattr(current, bit)
AttributeError: 'dict' object has no attribute 'autofocus'

During handling of the above exception, another exception occurred:

Traceback (most recent call last):
  File "/Library/WebServer/Documents/profiles-rest-api/profiles_api/lib/python3.6/site-packages/django/template/base.py", line 896, in _resolve_lookup
    current = current[int(bit)]
ValueError: invalid literal for int() with base 10: 'autofocus'

During handling of the above exception, another exception occurred:

Traceback (most recent call last):
  File "/Library/WebServer/Documents/profiles-rest-api/profiles_api/lib/python3.6/site-packages/django/template/base.py", line 903, in _resolve_lookup
    (bit, current))  # missing attribute
django.template.base.VariableDoesNotExist: Failed lookup for key [autofocus] in "{'base_template': 'input.html', 'input_type': 'text', 'template_pack': 'rest_framework/horizontal', 'renderer': <rest_framework.renderers.HTMLFormRenderer object at 0x1030d41d0>}"
Exception while resolving variable 'hide_label' in template 'rest_framework/horizontal/input.html'.
Traceback (most recent call last):
  File "/Library/WebServer/Documents/profiles-rest-api/profiles_api/lib/python3.6/site-packages/django/template/base.py", line 882, in _resolve_lookup
    current = current[bit]
KeyError: 'hide_label'

During handling of the above exception, another exception occurred:

Traceback (most recent call last):
  File "/Library/WebServer/Documents/profiles-rest-api/profiles_api/lib/python3.6/site-packages/django/template/base.py", line 890, in _resolve_lookup
    current = getattr(current, bit)
AttributeError: 'dict' object has no attribute 'hide_label'

During handling of the above exception, another exception occurred:

Traceback (most recent call last):
  File "/Library/WebServer/Documents/profiles-rest-api/profiles_api/lib/python3.6/site-packages/django/template/base.py", line 896, in _resolve_lookup
    current = current[int(bit)]
ValueError: invalid literal for int() with base 10: 'hide_label'

During handling of the above exception, another exception occurred:

Traceback (most recent call last):
  File "/Library/WebServer/Documents/profiles-rest-api/profiles_api/lib/python3.6/site-packages/django/template/base.py", line 903, in _resolve_lookup
    (bit, current))  # missing attribute
django.template.base.VariableDoesNotExist: Failed lookup for key [hide_label] in "{'base_template': 'input.html', 'input_type': 'number', 'template_pack': 'rest_framework/horizontal', 'renderer': <rest_framework.renderers.HTMLFormRenderer object at 0x1030d41d0>}"
Exception while resolving variable 'placeholder' in template 'rest_framework/horizontal/input.html'.
Traceback (most recent call last):
  File "/Library/WebServer/Documents/profiles-rest-api/profiles_api/lib/python3.6/site-packages/django/template/base.py", line 882, in _resolve_lookup
    current = current[bit]
KeyError: 'placeholder'

During handling of the above exception, another exception occurred:

Traceback (most recent call last):
  File "/Library/WebServer/Documents/profiles-rest-api/profiles_api/lib/python3.6/site-packages/django/template/base.py", line 890, in _resolve_lookup
    current = getattr(current, bit)
AttributeError: 'dict' object has no attribute 'placeholder'

During handling of the above exception, another exception occurred:

Traceback (most recent call last):
  File "/Library/WebServer/Documents/profiles-rest-api/profiles_api/lib/python3.6/site-packages/django/template/base.py", line 896, in _resolve_lookup
    current = current[int(bit)]
ValueError: invalid literal for int() with base 10: 'placeholder'

During handling of the above exception, another exception occurred:

Traceback (most recent call last):
  File "/Library/WebServer/Documents/profiles-rest-api/profiles_api/lib/python3.6/site-packages/django/template/base.py", line 903, in _resolve_lookup
    (bit, current))  # missing attribute
django.template.base.VariableDoesNotExist: Failed lookup for key [placeholder] in "{'base_template': 'input.html', 'input_type': 'number', 'template_pack': 'rest_framework/horizontal', 'renderer': <rest_framework.renderers.HTMLFormRenderer object at 0x1030d41d0>}"
Exception while resolving variable 'autofocus' in template 'rest_framework/horizontal/input.html'.
Traceback (most recent call last):
  File "/Library/WebServer/Documents/profiles-rest-api/profiles_api/lib/python3.6/site-packages/django/template/base.py", line 882, in _resolve_lookup
    current = current[bit]
KeyError: 'autofocus'

During handling of the above exception, another exception occurred:

Traceback (most recent call last):
  File "/Library/WebServer/Documents/profiles-rest-api/profiles_api/lib/python3.6/site-packages/django/template/base.py", line 890, in _resolve_lookup
    current = getattr(current, bit)
AttributeError: 'dict' object has no attribute 'autofocus'

During handling of the above exception, another exception occurred:

Traceback (most recent call last):
  File "/Library/WebServer/Documents/profiles-rest-api/profiles_api/lib/python3.6/site-packages/django/template/base.py", line 896, in _resolve_lookup
    current = current[int(bit)]
ValueError: invalid literal for int() with base 10: 'autofocus'

During handling of the above exception, another exception occurred:

Traceback (most recent call last):
  File "/Library/WebServer/Documents/profiles-rest-api/profiles_api/lib/python3.6/site-packages/django/template/base.py", line 903, in _resolve_lookup
    (bit, current))  # missing attribute
django.template.base.VariableDoesNotExist: Failed lookup for key [autofocus] in "{'base_template': 'input.html', 'input_type': 'number', 'template_pack': 'rest_framework/horizontal', 'renderer': <rest_framework.renderers.HTMLFormRenderer object at 0x1030d41d0>}"
"GET /api/user-process-history/ HTTP/1.1" 200 9985
(0.012) 
            SELECT c.relname, c.relkind
            FROM pg_catalog.pg_class c
            LEFT JOIN pg_catalog.pg_namespace n ON n.oid = c.relnamespace
            WHERE c.relkind IN ('r', 'v')
                AND n.nspname NOT IN ('pg_catalog', 'pg_toast')
                AND pg_catalog.pg_table_is_visible(c.oid); args=None
(0.004) SELECT "django_migrations"."app", "django_migrations"."name" FROM "django_migrations"; args=()
(0.002) SELECT "authtoken_token"."key", "authtoken_token"."user_id", "authtoken_token"."created", "profiles_api_userprofile"."id", "profiles_api_userprofile"."password", "profiles_api_userprofile"."last_login", "profiles_api_userprofile"."is_superuser", "profiles_api_userprofile"."email", "profiles_api_userprofile"."name", "profiles_api_userprofile"."lastname", "profiles_api_userprofile"."is_active", "profiles_api_userprofile"."is_staff", "profiles_api_userprofile"."country", "profiles_api_userprofile"."phone", "profiles_api_userprofile"."url_image", "profiles_api_userprofile"."state" FROM "authtoken_token" INNER JOIN "profiles_api_userprofile" ON ("authtoken_token"."user_id" = "profiles_api_userprofile"."id") WHERE "authtoken_token"."key" = '6412fe01d4f83677bafe2261d6dad0cc7405562b'; args=('6412fe01d4f83677bafe2261d6dad0cc7405562b',)
(0.001) SELECT "profiles_api_userprocesshistory"."id", "profiles_api_userprocesshistory"."user_profile_id", "profiles_api_userprocesshistory"."description", "profiles_api_userprocesshistory"."last_mod", "profiles_api_userprocesshistory"."remaining_storage", "profiles_api_userprocesshistory"."status" FROM "profiles_api_userprocesshistory" WHERE "profiles_api_userprocesshistory"."user_profile_id" = 5; args=(5,)
Exception while resolving variable 'hide_label' in template 'rest_framework/horizontal/select.html'.
Traceback (most recent call last):
  File "/Library/WebServer/Documents/profiles-rest-api/profiles_api/lib/python3.6/site-packages/django/template/base.py", line 882, in _resolve_lookup
    current = current[bit]
KeyError: 'hide_label'

During handling of the above exception, another exception occurred:

Traceback (most recent call last):
  File "/Library/WebServer/Documents/profiles-rest-api/profiles_api/lib/python3.6/site-packages/django/template/base.py", line 890, in _resolve_lookup
    current = getattr(current, bit)
AttributeError: 'dict' object has no attribute 'hide_label'

During handling of the above exception, another exception occurred:

Traceback (most recent call last):
  File "/Library/WebServer/Documents/profiles-rest-api/profiles_api/lib/python3.6/site-packages/django/template/base.py", line 896, in _resolve_lookup
    current = current[int(bit)]
ValueError: invalid literal for int() with base 10: 'hide_label'

During handling of the above exception, another exception occurred:

Traceback (most recent call last):
  File "/Library/WebServer/Documents/profiles-rest-api/profiles_api/lib/python3.6/site-packages/django/template/base.py", line 903, in _resolve_lookup
    (bit, current))  # missing attribute
django.template.base.VariableDoesNotExist: Failed lookup for key [hide_label] in "{'base_template': 'select.html', 'template_pack': 'rest_framework/horizontal', 'renderer': <rest_framework.renderers.HTMLFormRenderer object at 0x10fb192b0>}"
Exception while resolving variable 'allow_blank' in template 'rest_framework/horizontal/select.html'.
Traceback (most recent call last):
  File "/Library/WebServer/Documents/profiles-rest-api/profiles_api/lib/python3.6/site-packages/django/template/base.py", line 882, in _resolve_lookup
    current = current[bit]
TypeError: 'BoundField' object is not subscriptable

During handling of the above exception, another exception occurred:

Traceback (most recent call last):
  File "/Library/WebServer/Documents/profiles-rest-api/profiles_api/lib/python3.6/site-packages/django/template/base.py", line 890, in _resolve_lookup
    current = getattr(current, bit)
  File "/Library/WebServer/Documents/profiles-rest-api/profiles_api/lib/python3.6/site-packages/rest_framework/utils/serializer_helpers.py", line 69, in __getattr__
    return getattr(self._field, attr_name)
AttributeError: 'PrimaryKeyRelatedField' object has no attribute 'allow_blank'

During handling of the above exception, another exception occurred:

Traceback (most recent call last):
  File "/Library/WebServer/Documents/profiles-rest-api/profiles_api/lib/python3.6/site-packages/django/template/base.py", line 896, in _resolve_lookup
    current = current[int(bit)]
ValueError: invalid literal for int() with base 10: 'allow_blank'

During handling of the above exception, another exception occurred:

Traceback (most recent call last):
  File "/Library/WebServer/Documents/profiles-rest-api/profiles_api/lib/python3.6/site-packages/django/template/base.py", line 903, in _resolve_lookup
    (bit, current))  # missing attribute
django.template.base.VariableDoesNotExist: Failed lookup for key [allow_blank] in '<BoundField value= errors=None>'
(0.000) SELECT "profiles_api_userprofile"."id", "profiles_api_userprofile"."password", "profiles_api_userprofile"."last_login", "profiles_api_userprofile"."is_superuser", "profiles_api_userprofile"."email", "profiles_api_userprofile"."name", "profiles_api_userprofile"."lastname", "profiles_api_userprofile"."is_active", "profiles_api_userprofile"."is_staff", "profiles_api_userprofile"."country", "profiles_api_userprofile"."phone", "profiles_api_userprofile"."url_image", "profiles_api_userprofile"."state" FROM "profiles_api_userprofile" LIMIT 1000; args=()
Exception while resolving variable 'hide_label' in template 'rest_framework/horizontal/input.html'.
Traceback (most recent call last):
  File "/Library/WebServer/Documents/profiles-rest-api/profiles_api/lib/python3.6/site-packages/django/template/base.py", line 882, in _resolve_lookup
    current = current[bit]
KeyError: 'hide_label'

During handling of the above exception, another exception occurred:

Traceback (most recent call last):
  File "/Library/WebServer/Documents/profiles-rest-api/profiles_api/lib/python3.6/site-packages/django/template/base.py", line 890, in _resolve_lookup
    current = getattr(current, bit)
AttributeError: 'dict' object has no attribute 'hide_label'

During handling of the above exception, another exception occurred:

Traceback (most recent call last):
  File "/Library/WebServer/Documents/profiles-rest-api/profiles_api/lib/python3.6/site-packages/django/template/base.py", line 896, in _resolve_lookup
    current = current[int(bit)]
ValueError: invalid literal for int() with base 10: 'hide_label'

During handling of the above exception, another exception occurred:

Traceback (most recent call last):
  File "/Library/WebServer/Documents/profiles-rest-api/profiles_api/lib/python3.6/site-packages/django/template/base.py", line 903, in _resolve_lookup
    (bit, current))  # missing attribute
django.template.base.VariableDoesNotExist: Failed lookup for key [hide_label] in "{'base_template': 'input.html', 'input_type': 'text', 'template_pack': 'rest_framework/horizontal', 'renderer': <rest_framework.renderers.HTMLFormRenderer object at 0x10fb192b0>}"
Exception while resolving variable 'placeholder' in template 'rest_framework/horizontal/input.html'.
Traceback (most recent call last):
  File "/Library/WebServer/Documents/profiles-rest-api/profiles_api/lib/python3.6/site-packages/django/template/base.py", line 882, in _resolve_lookup
    current = current[bit]
KeyError: 'placeholder'

During handling of the above exception, another exception occurred:

Traceback (most recent call last):
  File "/Library/WebServer/Documents/profiles-rest-api/profiles_api/lib/python3.6/site-packages/django/template/base.py", line 890, in _resolve_lookup
    current = getattr(current, bit)
AttributeError: 'dict' object has no attribute 'placeholder'

During handling of the above exception, another exception occurred:

Traceback (most recent call last):
  File "/Library/WebServer/Documents/profiles-rest-api/profiles_api/lib/python3.6/site-packages/django/template/base.py", line 896, in _resolve_lookup
    current = current[int(bit)]
ValueError: invalid literal for int() with base 10: 'placeholder'

During handling of the above exception, another exception occurred:

Traceback (most recent call last):
  File "/Library/WebServer/Documents/profiles-rest-api/profiles_api/lib/python3.6/site-packages/django/template/base.py", line 903, in _resolve_lookup
    (bit, current))  # missing attribute
django.template.base.VariableDoesNotExist: Failed lookup for key [placeholder] in "{'base_template': 'input.html', 'input_type': 'text', 'template_pack': 'rest_framework/horizontal', 'renderer': <rest_framework.renderers.HTMLFormRenderer object at 0x10fb192b0>}"
Exception while resolving variable 'autofocus' in template 'rest_framework/horizontal/input.html'.
Traceback (most recent call last):
  File "/Library/WebServer/Documents/profiles-rest-api/profiles_api/lib/python3.6/site-packages/django/template/base.py", line 882, in _resolve_lookup
    current = current[bit]
KeyError: 'autofocus'

During handling of the above exception, another exception occurred:

Traceback (most recent call last):
  File "/Library/WebServer/Documents/profiles-rest-api/profiles_api/lib/python3.6/site-packages/django/template/base.py", line 890, in _resolve_lookup
    current = getattr(current, bit)
AttributeError: 'dict' object has no attribute 'autofocus'

During handling of the above exception, another exception occurred:

Traceback (most recent call last):
  File "/Library/WebServer/Documents/profiles-rest-api/profiles_api/lib/python3.6/site-packages/django/template/base.py", line 896, in _resolve_lookup
    current = current[int(bit)]
ValueError: invalid literal for int() with base 10: 'autofocus'

During handling of the above exception, another exception occurred:

Traceback (most recent call last):
  File "/Library/WebServer/Documents/profiles-rest-api/profiles_api/lib/python3.6/site-packages/django/template/base.py", line 903, in _resolve_lookup
    (bit, current))  # missing attribute
django.template.base.VariableDoesNotExist: Failed lookup for key [autofocus] in "{'base_template': 'input.html', 'input_type': 'text', 'template_pack': 'rest_framework/horizontal', 'renderer': <rest_framework.renderers.HTMLFormRenderer object at 0x10fb192b0>}"
Exception while resolving variable 'hide_label' in template 'rest_framework/horizontal/input.html'.
Traceback (most recent call last):
  File "/Library/WebServer/Documents/profiles-rest-api/profiles_api/lib/python3.6/site-packages/django/template/base.py", line 882, in _resolve_lookup
    current = current[bit]
KeyError: 'hide_label'

During handling of the above exception, another exception occurred:

Traceback (most recent call last):
  File "/Library/WebServer/Documents/profiles-rest-api/profiles_api/lib/python3.6/site-packages/django/template/base.py", line 890, in _resolve_lookup
    current = getattr(current, bit)
AttributeError: 'dict' object has no attribute 'hide_label'

During handling of the above exception, another exception occurred:

Traceback (most recent call last):
  File "/Library/WebServer/Documents/profiles-rest-api/profiles_api/lib/python3.6/site-packages/django/template/base.py", line 896, in _resolve_lookup
    current = current[int(bit)]
ValueError: invalid literal for int() with base 10: 'hide_label'

During handling of the above exception, another exception occurred:

Traceback (most recent call last):
  File "/Library/WebServer/Documents/profiles-rest-api/profiles_api/lib/python3.6/site-packages/django/template/base.py", line 903, in _resolve_lookup
    (bit, current))  # missing attribute
django.template.base.VariableDoesNotExist: Failed lookup for key [hide_label] in "{'base_template': 'input.html', 'input_type': 'text', 'template_pack': 'rest_framework/horizontal', 'renderer': <rest_framework.renderers.HTMLFormRenderer object at 0x10fb192b0>}"
Exception while resolving variable 'placeholder' in template 'rest_framework/horizontal/input.html'.
Traceback (most recent call last):
  File "/Library/WebServer/Documents/profiles-rest-api/profiles_api/lib/python3.6/site-packages/django/template/base.py", line 882, in _resolve_lookup
    current = current[bit]
KeyError: 'placeholder'

During handling of the above exception, another exception occurred:

Traceback (most recent call last):
  File "/Library/WebServer/Documents/profiles-rest-api/profiles_api/lib/python3.6/site-packages/django/template/base.py", line 890, in _resolve_lookup
    current = getattr(current, bit)
AttributeError: 'dict' object has no attribute 'placeholder'

During handling of the above exception, another exception occurred:

Traceback (most recent call last):
  File "/Library/WebServer/Documents/profiles-rest-api/profiles_api/lib/python3.6/site-packages/django/template/base.py", line 896, in _resolve_lookup
    current = current[int(bit)]
ValueError: invalid literal for int() with base 10: 'placeholder'

During handling of the above exception, another exception occurred:

Traceback (most recent call last):
  File "/Library/WebServer/Documents/profiles-rest-api/profiles_api/lib/python3.6/site-packages/django/template/base.py", line 903, in _resolve_lookup
    (bit, current))  # missing attribute
django.template.base.VariableDoesNotExist: Failed lookup for key [placeholder] in "{'base_template': 'input.html', 'input_type': 'text', 'template_pack': 'rest_framework/horizontal', 'renderer': <rest_framework.renderers.HTMLFormRenderer object at 0x10fb192b0>}"
Exception while resolving variable 'autofocus' in template 'rest_framework/horizontal/input.html'.
Traceback (most recent call last):
  File "/Library/WebServer/Documents/profiles-rest-api/profiles_api/lib/python3.6/site-packages/django/template/base.py", line 882, in _resolve_lookup
    current = current[bit]
KeyError: 'autofocus'

During handling of the above exception, another exception occurred:

Traceback (most recent call last):
  File "/Library/WebServer/Documents/profiles-rest-api/profiles_api/lib/python3.6/site-packages/django/template/base.py", line 890, in _resolve_lookup
    current = getattr(current, bit)
AttributeError: 'dict' object has no attribute 'autofocus'

During handling of the above exception, another exception occurred:

Traceback (most recent call last):
  File "/Library/WebServer/Documents/profiles-rest-api/profiles_api/lib/python3.6/site-packages/django/template/base.py", line 896, in _resolve_lookup
    current = current[int(bit)]
ValueError: invalid literal for int() with base 10: 'autofocus'

During handling of the above exception, another exception occurred:

Traceback (most recent call last):
  File "/Library/WebServer/Documents/profiles-rest-api/profiles_api/lib/python3.6/site-packages/django/template/base.py", line 903, in _resolve_lookup
    (bit, current))  # missing attribute
django.template.base.VariableDoesNotExist: Failed lookup for key [autofocus] in "{'base_template': 'input.html', 'input_type': 'text', 'template_pack': 'rest_framework/horizontal', 'renderer': <rest_framework.renderers.HTMLFormRenderer object at 0x10fb192b0>}"
Exception while resolving variable 'hide_label' in template 'rest_framework/horizontal/input.html'.
Traceback (most recent call last):
  File "/Library/WebServer/Documents/profiles-rest-api/profiles_api/lib/python3.6/site-packages/django/template/base.py", line 882, in _resolve_lookup
    current = current[bit]
KeyError: 'hide_label'

During handling of the above exception, another exception occurred:

Traceback (most recent call last):
  File "/Library/WebServer/Documents/profiles-rest-api/profiles_api/lib/python3.6/site-packages/django/template/base.py", line 890, in _resolve_lookup
    current = getattr(current, bit)
AttributeError: 'dict' object has no attribute 'hide_label'

During handling of the above exception, another exception occurred:

Traceback (most recent call last):
  File "/Library/WebServer/Documents/profiles-rest-api/profiles_api/lib/python3.6/site-packages/django/template/base.py", line 896, in _resolve_lookup
    current = current[int(bit)]
ValueError: invalid literal for int() with base 10: 'hide_label'

During handling of the above exception, another exception occurred:

Traceback (most recent call last):
  File "/Library/WebServer/Documents/profiles-rest-api/profiles_api/lib/python3.6/site-packages/django/template/base.py", line 903, in _resolve_lookup
    (bit, current))  # missing attribute
django.template.base.VariableDoesNotExist: Failed lookup for key [hide_label] in "{'base_template': 'input.html', 'input_type': 'number', 'template_pack': 'rest_framework/horizontal', 'renderer': <rest_framework.renderers.HTMLFormRenderer object at 0x10fb192b0>}"
Exception while resolving variable 'placeholder' in template 'rest_framework/horizontal/input.html'.
Traceback (most recent call last):
  File "/Library/WebServer/Documents/profiles-rest-api/profiles_api/lib/python3.6/site-packages/django/template/base.py", line 882, in _resolve_lookup
    current = current[bit]
KeyError: 'placeholder'

During handling of the above exception, another exception occurred:

Traceback (most recent call last):
  File "/Library/WebServer/Documents/profiles-rest-api/profiles_api/lib/python3.6/site-packages/django/template/base.py", line 890, in _resolve_lookup
    current = getattr(current, bit)
AttributeError: 'dict' object has no attribute 'placeholder'

During handling of the above exception, another exception occurred:

Traceback (most recent call last):
  File "/Library/WebServer/Documents/profiles-rest-api/profiles_api/lib/python3.6/site-packages/django/template/base.py", line 896, in _resolve_lookup
    current = current[int(bit)]
ValueError: invalid literal for int() with base 10: 'placeholder'

During handling of the above exception, another exception occurred:

Traceback (most recent call last):
  File "/Library/WebServer/Documents/profiles-rest-api/profiles_api/lib/python3.6/site-packages/django/template/base.py", line 903, in _resolve_lookup
    (bit, current))  # missing attribute
django.template.base.VariableDoesNotExist: Failed lookup for key [placeholder] in "{'base_template': 'input.html', 'input_type': 'number', 'template_pack': 'rest_framework/horizontal', 'renderer': <rest_framework.renderers.HTMLFormRenderer object at 0x10fb192b0>}"
Exception while resolving variable 'autofocus' in template 'rest_framework/horizontal/input.html'.
Traceback (most recent call last):
  File "/Library/WebServer/Documents/profiles-rest-api/profiles_api/lib/python3.6/site-packages/django/template/base.py", line 882, in _resolve_lookup
    current = current[bit]
KeyError: 'autofocus'

During handling of the above exception, another exception occurred:

Traceback (most recent call last):
  File "/Library/WebServer/Documents/profiles-rest-api/profiles_api/lib/python3.6/site-packages/django/template/base.py", line 890, in _resolve_lookup
    current = getattr(current, bit)
AttributeError: 'dict' object has no attribute 'autofocus'

During handling of the above exception, another exception occurred:

Traceback (most recent call last):
  File "/Library/WebServer/Documents/profiles-rest-api/profiles_api/lib/python3.6/site-packages/django/template/base.py", line 896, in _resolve_lookup
    current = current[int(bit)]
ValueError: invalid literal for int() with base 10: 'autofocus'

During handling of the above exception, another exception occurred:

Traceback (most recent call last):
  File "/Library/WebServer/Documents/profiles-rest-api/profiles_api/lib/python3.6/site-packages/django/template/base.py", line 903, in _resolve_lookup
    (bit, current))  # missing attribute
django.template.base.VariableDoesNotExist: Failed lookup for key [autofocus] in "{'base_template': 'input.html', 'input_type': 'number', 'template_pack': 'rest_framework/horizontal', 'renderer': <rest_framework.renderers.HTMLFormRenderer object at 0x10fb192b0>}"
"GET /api/user-process-history/ HTTP/1.1" 200 9985
